Workbook

Sheet 메인
B2: 랩쳐 정보 | E2: 조합 | M2: 대미지 유형별 딜량 (10+10초)
B3: 방어력 (31,784) | C3: 31784 | F3: 딜러 | G3: 서포터1 | H3: 서포터2 | I3: 서포터3 | J3: 서포터4 | M3: 일반공격 | N3: 스킬 | O3: 총딜량 | R3: 사이클 수 | S3: 사이클 시간 | T3: 버충시간
B4: 코어여부(노코0~상코1) | C4: 0 | E4: 니케 | F4: 신데렐라 | G4: 아니스 | H4: 마스트 | I4: 앵커 | M4: =O4-N4 -> 0.66281657 | N4: =SUMIF(G18:M18,"스킬",G16:M16) -> 1.7310042 | O4: =N16 -> 2.3938208 | R4: 4.5 | S4: =180/R4 -> 40 | T4: =S4/2-10 -> 10 | U4: 바소다
B5: 파츠코어여부(0or1) | C5: 0 | E5: 클래스 | F5: {=INDEX(딜러데이터!$1:$1, 1, MATCH($F$4, 딜러데이터!$1:$1, 0)+1)} -> 방어형 | G5: {=INDEX(서포터데이터!$1:$1, 1, MATCH(G$4, 서포터데이터!$1:$1, 0)+1)} -> 방어형 | H5: {=INDEX(서포터데이터!$1:$1, 1, MATCH(H$4, 서포터데이터!$1:$1, 0)+1)} -> 지원형 | I5: {=INDEX(서포터데이터!$1:$1, 1, MATCH(I$4, 서포터데이터!$1:$1, 0)+1)} -> 지원형 | J5: {=INDEX(서포터데이터!$1:$1, 1, MATCH(J$4, 서포터데이터!$1:$1, 0)+1)} -> #N/A | M5: =1-N5 -> 0.27688647 | N5: =SUMIF(G18:M18,"스킬",G16:M16)/N16 -> 0.72311353 | R5: 6 | S5: =180/R5 -> 30 | T5: =S5/2-10 -> 5 | U5: 느린 버충
B6: 코어픽셀수(계산방식검토필요) | C6: 50 | E6: 무기 | F6: {=INDEX(딜러데이터!$1:$1, 1, MATCH($F$4, 딜러데이터!$1:$1, 0)+2)} -> RL | G6: {=INDEX(서포터데이터!$1:$1, 1, MATCH(G$4, 서포터데이터!$1:$1, 0)+2)} -> RL | H6: {=INDEX(서포터데이터!$1:$1, 1, MATCH(H$4, 서포터데이터!$1:$1, 0)+2)} -> MG | I6: {=INDEX(서포터데이터!$1:$1, 1, MATCH(I$4, 서포터데이터!$1:$1, 0)+2)} -> RL | J6: {=INDEX(서포터데이터!$1:$1, 1, MATCH(J$4, 서포터데이터!$1:$1, 0)+2)} -> #N/A | R6: 6.5 | S6: =180/R6 -> 27.692308 | T6: =S6/2-10 -> 3.8461538 | U6: 13번째 버스트 완료
B7: 코어히트율(0-100%) | E7: 공격력 | F7: =IFERROR(HLOOKUP(F5, 니케스팩!$B$3:$E$5, 2, FALSE), 0) -> 90881.72 | G7: =IFERROR(HLOOKUP(G5, 니케스팩!$B$3:$E$5, 2, FALSE), 0) -> 90881.72 | H7: =IFERROR(HLOOKUP(H5, 니케스팩!$B$3:$E$5, 2, FALSE), 0) -> 109843.9 | I7: =IFERROR(HLOOKUP(I5, 니케스팩!$B$3:$E$5, 2, FALSE), 0) -> 109843.9 | J7: =IFERROR(HLOOKUP(J5, 니케스팩!$B$3:$E$5, 2, FALSE), 0) -> 0 | L7: 버스트 사이클 횟수별 딜량 | R7: 6.7 | S7: =180/R7 -> 26.865672 | T7: =S7/2-10 -> 3.4328358 | U7: 14번째 버스트 시전
B8: 적정거리여부(0or1) | C8: 0 | E8: 체력 | F8: =IFERROR(HLOOKUP(F5, 니케스팩!$B$3:$E$5, 3, FALSE), 0) -> 3669974.5 | G8: =IFERROR(HLOOKUP(G5, 니케스팩!$B$3:$E$5, 3, FALSE), 0) -> 3669974.5 | H8: =IFERROR(HLOOKUP(H5, 니케스팩!$B$3:$E$5, 3, FALSE), 0) -> 3385513.8 | I8: =IFERROR(HLOOKUP(I5, 니케스팩!$B$3:$E$5, 3, FALSE), 0) -> 3385513.8 | J8: =IFERROR(HLOOKUP(J5, 니케스팩!$B$3:$E$5, 3, FALSE), 0) -> 0 | L8: 6사이클 | M8: 6.5사이클(선) | N8: 6.5사이클(후) | O8: 7사이클 | P8: 8 | Q8: 9 | R8: 7 | S8: =180/R8 -> 25.714286 | T8: =S8/2-10 -> 2.8571429 | U8: 14번째 버스트 완료
B9: 우월코드여부(0or1) | C9: 0 | E9: 방어력 | F9: =IFERROR(INDEX(니케스팩!$C$7:$E$12, MATCH(F6, 니케스팩!$B$7:$B$12, 0), MATCH(F5, 니케스팩!$C$3:$E$3, 0)), 0) -> 24091.18 | G9: =IFERROR(INDEX(니케스팩!$C$7:$E$12, MATCH(G6, 니케스팩!$B$7:$B$12, 0), MATCH(G5, 니케스팩!$C$3:$E$3, 0)), 0) -> 24091.18 | H9: =IFERROR(INDEX(니케스팩!$C$7:$E$12, MATCH(H6, 니케스팩!$B$7:$B$12, 0), MATCH(H5, 니케스팩!$C$3:$E$3, 0)), 0) -> 20016.52 | I9: =IFERROR(INDEX(니케스팩!$C$7:$E$12, MATCH(I6, 니케스팩!$B$7:$B$12, 0), MATCH(I5, 니케스팩!$C$3:$E$3, 0)), 0) -> 22235.1 | J9: =IFERROR(INDEX(니케스팩!$C$7:$E$12, MATCH(J6, 니케스팩!$B$7:$B$12, 0), MATCH(J5, 니케스팩!$C$3:$E$3, 0)), 0) -> 0 | L9: =N16*6 -> 14.362925 | M9: =(N14*7+N15*6) -> 16.125447 | N9: =(N15*7+N14*6) -> 14.994223 | O9: =N16*7 -> 16.756745 | P9: =N16*8 -> 19.150566 | Q9: =N16*9 -> 21.544387
L10: 주의: 스택형 스킬의 초반 딜로스는 고려하지 않음 | R10: 7.5 | S10: =180/R10 -> 24 | T10: =S10/2-7.5 -> 4.5 | U10: 아르카나-루주 (8번째 아르카나 버스트만 완료)
B11: 계산방식 | R11: 7.8 | S11: =180/R11 -> 23.076923 | T11: =S11/2-7.5 -> 4.0384615 | U11: 아르카나-루주 (15번째 버스트 시전)
B12: 탄창고려(탄창계산기따로만들필요있음) | G12: 버스트사용딜 | H12: 버스트추가딜 | I12: 대미지1 | J12: 대미지2 | K12: 대미지3 | L12: 대미지4 | M12: 버스트종료후 | N12: 합 | O12: 비율 | R12: 8.5 | S12: =180/R12 -> 21.176471 | T12: =S12/2-7.5 -> 3.0882353 | U12: 아르카나-세이렌
B13: 차속계산(0or1) | C13: 0 | G13: =딜량계산!C4 -> 버스트 | H13: =딜량계산!D4 -> 버스투추가 | I13: =딜량계산!E4 -> 평타 | J13: =딜량계산!F4 -> 풀차지 | K13: =딜량계산!G4 | L13: =딜량계산!H4 | M13: =딜량계산!M4 | R13: 9 | S13: =180/R13 -> 20 | T13: =S13/2-7.5 -> 2.5 | U13: 아르카나-세이렌 이론
B14: 버충시간고려(기본3.85) | F14: 본인버스트 | G14: =IF(딜량계산!C5=0,"",딜량계산!C5/100000000) -> 0.70052093 | H14: =IF(딜량계산!D5=0,"",딜량계산!D5/100000000) -> 0.34785779 | I14: =IF(딜량계산!E5+딜량계산!I5=0,"",(딜량계산!E5+딜량계산!I5)/100000000) -> 0.32442152 | J14: =IF(딜량계산!F5+딜량계산!J5=0,"",(딜량계산!F5+딜량계산!J5)/100000000) -> 0.38972172 | K14: =IF(딜량계산!G5+딜량계산!K5=0,"",(딜량계산!G5+딜량계산!K5)/100000000) | L14: =IF(딜량계산!H5+딜량계산!L5=0,"",(딜량계산!H5+딜량계산!L5)/100000000) | M14: =IF(딜량계산!M5=0,"",딜량계산!M5/100000000) | N14: =SUM(G14:M14) -> 1.762522 | O14: =N14/$N$16 -> 0.73627983
B15: 선버0/후버1 | F15: 타인버스트 | I15: =IF(딜량계산!N5+딜량계산!R5=0,"",(딜량계산!N5+딜량계산!R5)/100000000) -> 0.33839505 | J15: =IF(딜량계산!O5+딜량계산!S5=0,"",(딜량계산!O5+딜량계산!S5)/100000000) -> 0.29290376 | K15: =IF(딜량계산!P5+딜량계산!T5=0,"",(딜량계산!P5+딜량계산!T5)/100000000) | L15: =IF(딜량계산!Q5+딜량계산!U5=0,"",(딜량계산!Q5+딜량계산!U5)/100000000) | N15: =SUM(I15:L15) -> 0.63129881 | O15: =N15/$N$16 -> 0.26372017
F16: 합 | G16: =IF(SUM(G14:G15)=0, "", SUM(G14:G15)) -> 0.70052093 | H16: =IF(SUM(H14:H15)=0, "", SUM(H14:H15)) -> 0.34785779 | I16: =IF(SUM(I14:I15)=0, "", SUM(I14:I15)) -> 0.66281657 | J16: =IF(SUM(J14:J15)=0, "", SUM(J14:J15)) -> 0.68262548 | K16: =IF(SUM(K14:K15)=0, "", SUM(K14:K15)) | L16: =IF(SUM(L14:L15)=0, "", SUM(L14:L15)) | M16: =IF(SUM(M14:M15)=0, "", SUM(M14:M15)) | N16: =N15+N14 -> 2.3938208 | O16: (1사이클)
B17: 딜러 장비옵션 | F17: 비율 | G17: =IFERROR(G16/$N$16, "") -> 0.29263717 | H17: =IFERROR(H16/$N$16, "") -> 0.14531488 | I17: =IFERROR(I16/$N$16, "") -> 0.27688647 | J17: =IFERROR(J16/$N$16, "") -> 0.28516148 | K17: =IFERROR(K16/$N$16, "") | L17: =IFERROR(L16/$N$16, "") | M17: =IFERROR(M16/$N$16, "") | N17: =N16*7 -> 16.756745 | O17: (7사이클)
B18: 우월코드 대미지 | C18: 0.8 | D18: 23.56 | G18: =IF(딜량계산!C15=0,"",딜량계산!C15) -> 스킬 | H18: =IF(딜량계산!D15=0,"",딜량계산!D15) -> 스킬 | I18: =IF(딜량계산!E15=0,"",딜량계산!E15) -> RL | J18: =IF(딜량계산!F15=0,"",딜량계산!F15) -> 스킬 | K18: =IF(딜량계산!G15=0,"",딜량계산!G15) | L18: =IF(딜량계산!H15=0,"",딜량계산!H15) | M18: =IF(딜량계산!M15=0,"",딜량계산!M15)
B19: 공격력 | C19: 0.2 | D19: 11.81
B20: 최대 장탄 수 | C20: 1.2 | D20: 68.93
B21: 크리티컬 확률 | C21: 0 | D21: 5.7 | P21: =1.83/1.7 -> 1.0764706
B22: 크리티컬 대미지 | C22: 0 | D22: 16.44
B23: 차지 대미지 | C23: 0 | D23: 11.81
B24: 차지 속도 | C24: 0 | D24: 4.92
B25: 명중률 | C25: 0 | D25: 11.81
B26: 방어력 | C26: 0 | D26: 11.81
B29: 소장품/돌파&코어강화/큐브/장비4종/콘솔 | C29: 스킬은내비두
B30: 소장품 배율 문제 해결
J31: 50 | K31: 0.18 | N31: =0.64+0.32 -> 0.96
B32: 샷건코힛율 | C32: 조사 필요 | D32: SG | E32: d=-2.14x+240 | F32: 코어직경=c | G32: 코힛률=c2/d2 | I32: 1 | J32: =240-K31*218 -> 200.76 | K32: =I32*(J31/MAX(J31,(240-K31*218))) -> 0.2490536
D33: SMG | E33: d=-1x+110 | J33: =110-K31*100 -> 92 | K33: =MIN(1,(J31/MAX(J31,(110-K31*100)))) -> 0.54347826
D34: AR | E34: d=-0.69x+76 | I34: 1 | J34: =76-K31*69 -> 63.58 | K34: =I34*MIN(1,(J31/MAX(J31,(76-K31*69)))) -> 0.78641082
J35: https://arca.live/b/nikketgv/96243965
J36: 관계식 알아보기
B38: 장탄/탄창/재장 딜량 보정 | D38: >> 재장전시간/탄환소모시간 비율 계산해서 평타 횟수 보정
D39: 풀버스트 10초간 재장전을 하지 않는 경우에는 의미가 없음 (재장전 컨을 한다는 가정에)
D40: AR,SMG 같은 경우에는 유의미할수도
M42: 장탄고려보정 | N42: 공격시간/(공격시간+재장시간)
M43: 공격시간 | N43: 장탄/(기본공속(1+공속증가))
F44: px_c | M44: 재장시간 | N44: 재장*(1-재장속)+예열
F45: 50
...

Sheet 니케목록
A1: 서포터목록 | B1: 주의사항 | D1: 딜러목록 | E1: 주의사항
A2: {=TRANSPOSE(INDEX(서포터데이터!$1:$1,3+(COLUMN($A$2:$ZX$2)-1)*6))} -> 세이렌 | D2: {=TRANSPOSE(INDEX(딜러데이터!$1:$1,3+(COLUMN($A$2:$ZX$2)-1)*6))} -> 라피
A3: 세이렌(토템) | D3: 흑련(앨) | E3: 앨리스가 있다고 가정
A4: 크라운 | D4: 흑련
A5: 크라운(노힐) | D5: 신데렐라
A6: 크라운(노힐토템) | D6: 미하라
A7: 헬름 | B7: 애장품 기준, 토템 | D7: 미하라(미) | E7: 미란다2스 1발 크확 적용
A8: 세이렌(토템) | D8: 미하라(토템)
A9: 마스트 | B9: 선버스트 사용, 앵커와 함께 조합 가정 | D9: 수로시
A10: 앵커 | B10: 후버스트 사용, 이지스와 함께 조합 가정 (실제로 함께조합 아니어도 딜버프에는 영향 없음) | D10: 수로시(레오나)
A11: 마스트(타버) | B11: 선버스트 사용, 앵커와 함께 조합 가정 | D11: 헬름
A12: 앵커(자버) | B12: 후버스트 사용, 이지스와 함께 조합 가정 (실제로 함께조합 아니어도 딜버프에는 영향 없음) | D12: 레드후드
A13: 리타 | D13: 앨리스 | E13: 35발
A14: 볼륨 | D14: 이사벨
A15: 블랑 | B15: 777와 조합 | D15: 클루드
A16: 누아르 | B16: 토템(777시너지와 샷건버프는 버스트에만 있어서 토템이면 조합 상관 없음) | D16: 드레이크
A17: 루주 | D17: 수니스
A18: 레드후드(자버) | D18: 수니스(프바)
A19: 레드후드(타버) | D19: 아인
A20: 나가(단독) | D20: 아인(미)
A21: 나가 | D21: 홍련 | E21: 체력 50% 이하
A22: 티아 | D22: 모더니아 | E22: 토템
A23: 나가(토템) | D23: 클이든 | E23: 버스트 사용
A24: 은화(단독) | D24: 클이든(토템)
A25: 은화 | D25: 엑시아
A26: 엠마 | D26: 메프바
A27: 토브 | B27: 샷건 버프 적용 | D27: 메프바(레오나)
A28: 드레이크 | B28: 샷건 버프 적용, 애장품 기준 | D28: 마나
A29: 레오나 | B29: 샷건 버프 적용 | D29: 율리아
A30: 아르카나(이사벨) | B30: 이사벨에만 적용 버프, 트릭: 자버후반은 시공증 -9999% (다른 서포터의 버프 지속 시간 문제 있음) | D30: 라플라스
A31: 아르카나(전격) | B31: 아사벨과 함꼐 사용했을 때 다른 딜러에게 들어가는 버프, 트릭: 타버후반은 시공증 -9999% | D31: 라플라스(파츠)
A32: 그레이브 | D32: 이브
A33: 동디(SR) | D33: 레이븐
A34: 동디 | D34: 레이븐(파츠) | E34: 미란다2스 1발 크확 적용
A35: 수니스 | B35: 전격 버프 적용 | D35: 스화
A36: 클이든 | B36: 전격 버프 적용, 토템 | D36: 맥스웰
A37: 클이든(3버) | D37: 바밀크
A38: 클루드 | B38: 20초마다 버스트 사용, 홍련에게 적용되는 버프 | D38: 수레그 | E38: 토템
A39: 트리나(홍련) | B39: 홍련 버스트 때만 버스트 사용, 홍련에게 적용되는 버프 | D39: 클드밀라
A40: 트리나(자버홍련) | B40: 20초마다 버스트, 홍련 아닌 딜러에게 적용되는 버프 | D40: 수쿠라
...

Sheet 니케스팩
M1: 평타 | N1: 공격횟수/10초 | O1: 알려진 값들 | P1: 기본탄착군 | Q1: 비고
B2: 레포 기준: Lv400 3돌 0코강 호감30 장비T5x4 소장품SR15 큐브재장15 콘솔180/100/100 | M2: AR | N2: 120 | O2: 120, 111 | P2: 75
B3: 기준 | C3: 화력형 | D3: 지원형 | E3: 방어형 | G3: 기본 | H3: 화력형 | I3: 지원형 | J3: 방어형 | M3: SG | N3: 15.15 | O3: 15.15 | P3: 250
B4: 공격력 | C4: =H4+((H4*0.02+20)*3+H15+$E15)*(1+0.02*0)+SUM(H19,H23,H27,H31)+$C15+$D15 -> 128806.08 | D4: =I4+((I4*0.02+20)*3+I15+$E15)*(1+0.02*0)+SUM(I19,I23,I27,I31)+$C15+$D15 -> 109843.9 | E4: =J4+((J4*0.02+20)*3+J15+$E15)*(1+0.02*0)+SUM(J19,J23,J27,J31)+$C15+$D15 -> 90881.72 | G4: 공격력 | H4: 90318 | I4: 75265 | J4: 60212 | M4: SMG | N4: 200 | O4: 200, 133 | P4: 110
B5: 체력 | C5: =H5+((H5*0.02+20)*3+H16+$E16)*(1+0.02*0)+SUM(H20,H24,H28,H32)+$C16+$D16 -> 3101116 | D5: =I5+((I5*0.02+20)*3+I16+$E16)*(1+0.02*0)+SUM(I20,I24,I28,I32)+$C16+$D16 -> 3385513.8 | E5: =J5+((J5*0.02+20)*3+J16+$E16)*(1+0.02*0)+SUM(J20,J24,J28,J32)+$C16+$D16 -> 3669974.5 | G5: 체력 | H5: 2032167 | I5: 2257963 | J5: 2483759 | M5: MG | N5: 550 | O5: 520, 550, 600 | P5: 10 | Q5: 예열 2.25초~47발(https://gall.dcinside.com/mgallery/board/view/?id=gov&no=3047564), 편하게 계산하려면 1.5초 예열 0발, 재장전시간 짧으면 예열 줄어듬
B6: 방어력 | G6: 방어력 | M6: RL | N6: 8.13 | O6: 8.13, 8.23 | P6: 1
B7: AR | C7: =H7+((H7*0.02+20)*3+H$17+$E$17)*(1+0.02*0)+SUM(H$21,H$25,H$29,H$33)+$C$17+$D$17 -> 20728.88 | D7: =I7+((I7*0.02+20)*3+I$17+$E$17)*(1+0.02*0)+SUM(I$21,I$25,I$29,I$33)+$C$17+$D$17 -> 22625.18 | E7: =J7+((J7*0.02+20)*3+J$17+$E$17)*(1+0.02*0)+SUM(J$21,J$25,J$29,J$33)+$C$17+$D$17 -> 24520.48 | G7: AR | H7: 13548 | I7: 15053 | J7: 16558 | M7: SR | N7: 8.13 | O7: 8.13, 8.23 | P7: 10
B8: SR | C8: =H8+((H8*0.02+20)*3+H$17+$E$17)*(1+0.02*0)+SUM(H$21,H$25,H$29,H$33)+$C$17+$D$17 -> 18427.62 | D8: =I8+((I8*0.02+20)*3+I$17+$E$17)*(1+0.02*0)+SUM(I$21,I$25,I$29,I$33)+$C$17+$D$17 -> 20068.46 | E8: =J8+((J8*0.02+20)*3+J$17+$E$17)*(1+0.02*0)+SUM(J$21,J$25,J$29,J$33)+$C$17+$D$17 -> 21709.36 | G8: SR | H8: 11377 | I8: 12641 | J8: 13906 | M8: 특수무기
B9: SMG | C9: =H9+((H9*0.02+20)*3+H$17+$E$17)*(1+0.02*0)+SUM(H$21,H$25,H$29,H$33)+$C$17+$D$17 -> 18733.96 | D9: =I9+((I9*0.02+20)*3+I$17+$E$17)*(1+0.02*0)+SUM(I$21,I$25,I$29,I$33)+$C$17+$D$17 -> 20408.72 | E9: =J9+((J9*0.02+20)*3+J$17+$E$17)*(1+0.02*0)+SUM(J$21,J$25,J$29,J$33)+$C$17+$D$17 -> 22083.54 | G9: SMG | H9: 11666 | I9: 12962 | J9: 14259 | M9: 라피유탄 | N9: =N5/10 -> 55 | P9: 1
B10: SG | C10: =H10+((H10*0.02+20)*3+H$17+$E$17)*(1+0.02*0)+SUM(H$21,H$25,H$29,H$33)+$C$17+$D$17 -> 20154.36 | D10: =I10+((I10*0.02+20)*3+I$17+$E$17)*(1+0.02*0)+SUM(I$21,I$25,I$29,I$33)+$C$17+$D$17 -> 21987.06 | E10: =J10+((J10*0.02+20)*3+J$17+$E$17)*(1+0.02*0)+SUM(J$21,J$25,J$29,J$33)+$C$17+$D$17 -> 23819.82 | G10: SG | H10: 13006 | I10: 14451 | J10: 15897 | M10: 수로시섬광SG | N10: 15.15 | P10: 10 | Q10: 명중률만 고려하면 35.1인데 관통범위가 어느정도인지 모름. 관통범위 픽셀수를 빼야함
B11: RL | C11: =H11+((H11*0.02+20)*3+H$17+$E$17)*(1+0.02*0)+SUM(H$21,H$25,H$29,H$33)+$C$17+$D$17 -> 20376.96 | D11: =I11+((I11*0.02+20)*3+I$17+$E$17)*(1+0.02*0)+SUM(I$21,I$25,I$29,I$33)+$C$17+$D$17 -> 22235.1 | E11: =J11+((J11*0.02+20)*3+J$17+$E$17)*(1+0.02*0)+SUM(J$21,J$25,J$29,J$33)+$C$17+$D$17 -> 24091.18 | G11: RL | H11: 13216 | I11: 14685 | J11: 16153
B12: MG | C12: =H12+((H12*0.02+20)*3+H$17+$E$17)*(1+0.02*0)+SUM(H$21,H$25,H$29,H$33)+$C$17+$D$17 -> 18380.98 | D12: =I12+((I12*0.02+20)*3+I$17+$E$17)*(1+0.02*0)+SUM(I$21,I$25,I$29,I$33)+$C$17+$D$17 -> 20016.52 | E12: =J12+((J12*0.02+20)*3+J$17+$E$17)*(1+0.02*0)+SUM(J$21,J$25,J$29,J$33)+$C$17+$D$17 -> 21652.12 | G12: MG | H12: 11333 | I12: 12592 | J12: 13852
C14: 큐브15 | D14: 소장품15 | E14: 콘솔180/100 | G14: 호감도30 | H14: 화력형 | I14: 지원형 | J14: 방어형
B15: 공격력 | C15: 2780 | D15: 9688 | E15: =25*100 -> 2500 | G15: 공격력 | H15: 1640 | I15: 1367 | J15: 1094
B16: 체력 | C16: 83400 | D16: 301800 | E16: =750*100+450*180 -> 156000 | G16: 체력 | H16: 36897 | I16: 40997 | J16: 45097
B17: 방어력 | C17: 552 | D17: 2058 | E17: =5*100+5*100 -> 1000 | G17: 방어력 | H17: 246 | I17: 273 | J17: 300
G18: 뚝5
G19: 공격력 | H19: 9021 | I19: 7518 | J19: 6015
G20: 체력 | H20: 73771 | I20: 81969 | J20: 90167
G21: 방어력
G22: 장5
G23: 공격력 | H23: 5741 | I23: 4783 | J23: 3827
G24: 체력
G25: 방어력 | H25: 981 | I25: 1091 | J25: 1200
E26: 0.23, 0.215 | G26: 갑5
E27: 0.23, 0.215 | G27: 공격력 | H27: 1639 | I27: 1367 | J27: 1093
G28: 체력 | H28: 239760 | I28: 266400 | J28: 293040
G29: 방어력
G30: 신5
G31: 공격력
G32: 체력 | H32: 55331 | I32: 61447 | J32: 67626
G33: 방어력 | H33: 1471 | I33: 1635 | J33: 1799
C39: 지금은 이용 안 하지만 나중엔 사용할수도?
B40: 돌파 | C40: 3 | D40: 3 | E40: 3 | F40: 3 | G40: 3
B41: 코어강화 | C41: 0 | D41: 0 | E41: 0 | F41: 0 | G41: 0
B42: 호감도 | C42: 30 | D42: 30 | E42: 30 | F42: 30 | G42: 30
B43: 뚝 | C43: 5 | D43: 5 | E43: 5 | F43: 5 | G43: 5
B44: 장 | C44: 5 | D44: 5 | E44: 5 | F44: 5 | G44: 5
B45: 갑 | C45: 5 | D45: 5 | E45: 5 | F45: 5 | G45: 5
B46: 신 | C46: 5 | D46: 5 | E46: 5 | F46: 5 | G46: 5
...

Sheet 딜량계산
C1: 버스트시전 | E1: 자버초반 | I1: 자버후반 | M1: 자버이후 | N1: 타버초반 | R1: 타버후반
C2: =C5+D5 -> 1.0483787e+08 | E2: =SUM(E5:H5) -> 37661301 | I2: =SUM(I5:L5) -> 33753023 | M2: =M5 -> 0 | N2: =SUM(N5:Q5) -> 37423712 | R2: =SUM(R5:U5) -> 25706168
A3: 딜러데이터(스킬) | B3: =메인!F4 -> 신데렐라 | E3: 대미지1 | F3: 대미지2 | G3: 대미지3 | H3: 대미지4 | I3: 대미지1 | J3: 대미지2 | K3: 대미지3 | L3: 대미지4 | M3: 풀버스트후 | N3: 대미지1 | O3: 대미지2 | P3: 대미지3 | Q3: 대미지4 | R3: 대미지1 | S3: 대미지2 | T3: 대미지3 | U3: 대미지4
A4: 버프요약(버프) | C4: {=IF(ISBLANK(INDEX(딜러데이터!$54:$54, 1, MATCH(메인!$F$4, 딜러데이터!$1:$1, 0)+C$8)), "", INDEX(딜러데이터!$54:$54, 1, MATCH(메인!$F$4, 딜러데이터!$1:$1, 0)+C$8))} -> 버스트 | D4: {=IF(ISBLANK(INDEX(딜러데이터!$54:$54, 1, MATCH(메인!$F$4, 딜러데이터!$1:$1, 0)+D$8)), "", INDEX(딜러데이터!$54:$54, 1, MATCH(메인!$F$4, 딜러데이터!$1:$1, 0)+D$8))} -> 버스투추가 | E4: {=IF(ISBLANK(INDEX(딜러데이터!$54:$54, 1, MATCH(메인!$F$4, 딜러데이터!$1:$1, 0)+E$8)), "", INDEX(딜러데이터!$54:$54, 1, MATCH(메인!$F$4, 딜러데이터!$1:$1, 0)+E$8))} -> 평타 | F4: {=IF(ISBLANK(INDEX(딜러데이터!$54:$54, 1, MATCH(메인!$F$4, 딜러데이터!$1:$1, 0)+F$8)), "", INDEX(딜러데이터!$54:$54, 1, MATCH(메인!$F$4, 딜러데이터!$1:$1, 0)+F$8))} -> 풀차지 | G4: {=IF(ISBLANK(INDEX(딜러데이터!$54:$54, 1, MATCH(메인!$F$4, 딜러데이터!$1:$1, 0)+G$8)), "", INDEX(딜러데이터!$54:$54, 1, MATCH(메인!$F$4, 딜러데이터!$1:$1, 0)+G$8))} | H4: {=IF(ISBLANK(INDEX(딜러데이터!$54:$54, 1, MATCH(메인!$F$4, 딜러데이터!$1:$1, 0)+H$8)), "", INDEX(딜러데이터!$54:$54, 1, MATCH(메인!$F$4, 딜러데이터!$1:$1, 0)+H$8))} | I4: {=IF(ISBLANK(INDEX(딜러데이터!$54:$54, 1, MATCH(메인!$F$4, 딜러데이터!$1:$1, 0)+I$8)), "", INDEX(딜러데이터!$54:$54, 1, MATCH(메인!$F$4, 딜러데이터!$1:$1, 0)+I$8))} -> 평타 | J4: {=IF(ISBLANK(INDEX(딜러데이터!$54:$54, 1, MATCH(메인!$F$4, 딜러데이터!$1:$1, 0)+J$8)), "", INDEX(딜러데이터!$54:$54, 1, MATCH(메인!$F$4, 딜러데이터!$1:$1, 0)+J$8))} -> 풀차지 | ... L4: {=IF(ISBLANK(INDEX(딜러데이터!$54:$54, 1, MATCH(메인!$F$4, 딜러데이터!$1:$1, 0)+L$8)), "", INDEX(딜러데이터!$54:$54, 1, MATCH(메인!$F$4, 딜러데이터!$1:$1, 0)+L$8))} | M4: {=IF(ISBLANK(INDEX(딜러데이터!$67:$67, 1, MATCH(메인!$F$4, 딜러데이터!$1:$1, 0)+M$8)), "", INDEX(딜러데이터!$67:$67, 1, MATCH(메인!$F$4, 딜러데이터!$1:$1, 0)+M$8))} | N4: {=IF(ISBLANK(INDEX(딜러데이터!$54:$54, 1, MATCH(메인!$F$4, 딜러데이터!$1:$1, 0)+N$8)), "", INDEX(딜러데이터!$54:$54, 1, MATCH(메인!$F$4, 딜러데이터!$1:$1, 0)+N$8))} -> 평타 | O4: {=IF(ISBLANK(INDEX(딜러데이터!$54:$54, 1, MATCH(메인!$F$4, 딜러데이터!$1:$1, 0)+O$8)), "", INDEX(딜러데이터!$54:$54, 1, MATCH(메인!$F$4, 딜러데이터!$1:$1, 0)+O$8))} -> 풀차지 | P4: {=IF(ISBLANK(INDEX(딜러데이터!$54:$54, 1, MATCH(메인!$F$4, 딜러데이터!$1:$1, 0)+P$8)), "", INDEX(딜러데이터!$54:$54, 1, MATCH(메인!$F$4, 딜러데이터!$1:$1, 0)+P$8))} | Q4: {=IF(ISBLANK(INDEX(딜러데이터!$54:$54, 1, MATCH(메인!$F$4, 딜러데이터!$1:$1, 0)+Q$8)), "", INDEX(딜러데이터!$54:$54, 1, MATCH(메인!$F$4, 딜러데이터!$1:$1, 0)+Q$8))} | R4: {=IF(ISBLANK(INDEX(딜러데이터!$54:$54, 1, MATCH(메인!$F$4, 딜러데이터!$1:$1, 0)+R$8)), "", INDEX(딜러데이터!$54:$54, 1, MATCH(메인!$F$4, 딜러데이터!$1:$1, 0)+R$8))} -> 평타 | S4: {=IF(ISBLANK(INDEX(딜러데이터!$54:$54, 1, MATCH(메인!$F$4, 딜러데이터!$1:$1, 0)+S$8)), "", INDEX(딜러데이터!$54:$54, 1, MATCH(메인!$F$4, 딜러데이터!$1:$1, 0)+S$8))} -> 풀차지 | T4: {=IF(ISBLANK(INDEX(딜러데이터!$54:$54, 1, MATCH(메인!$F$4, 딜러데이터!$1:$1, 0)+T$8)), "", INDEX(딜러데이터!$54:$54, 1, MATCH(메인!$F$4, 딜러데이터!$1:$1, 0)+T$8))} | U4: {=IF(ISBLANK(INDEX(딜러데이터!$54:$54, 1, MATCH(메인!$F$4, 딜러데이터!$1:$1, 0)+U$8)), "", INDEX(딜러데이터!$54:$54, 1, MATCH(메인!$F$4, 딜러데이터!$1:$1, 0)+U$8))}
A5: 계산요약(on/off) | B5: 대미지 | C5: =C19*C9 -> 70052093 | D5: =D19*D9 -> 34785779 | E5: =E19*E9 -> 17108804 | F5: =F19*F9 -> 20552497 | G5: =G19*G9 -> 0 | H5: =H19*H9 -> 0 | I5: =I19*I9 -> 15333348 | J5: =J19*J9 -> 18419675 | ... U5: =U19*U9 -> 0
C7: 본인 풀버 직전 | D7: 본인 풀버 시 | E7: 본인 풀버 전반 | F7: 본인 풀버 전반 | G7: 본인 풀버 전반 | H7: 본인 풀버 전반 | I7: 본인 풀버 후반 | J7: 본인 풀버 후반 | K7: 본인 풀버 후반 | L7: 본인 풀버 후반 | M7: 본인 풀버 이후 | N7: 타인 풀버 초반 | O7: 타인 풀버 초반 | P7: 타인 풀버 초반 | Q7: 타인 풀버 초반 | R7: 타인 풀버 후반 | S7: 타인 풀버 후반 | T7: 타인 풀버 후반 | U7: 타인 풀버 후반
A8: 버스트 보너스 구분, 공격횟수 때도 사용 중 | B8: 스킬index | C8: 0 | D8: 1 | E8: 2 | F8: 3 | G8: 4 | H8: 5 | I8: 2 | J8: 3 | K8: 4 | L8: 5 | M8: 0 | N8: 2 | O8: 3 | P8: 4 | Q8: 5 | R8: 2 | S8: 3 | T8: 4 | U8: 5
B9: 횟수/발수(5초) | C9: =IF(OR(C8=0,C8=1),C10,0.5*IF(COUNTIF(C15:C18,"*차지"),C11,C10*IF(COUNTIF(C15,"*SG"),1+C67,1))) -> 10 | D9: =IF(OR(D8=0,D8=1),D10,0.5*IF(COUNTIF(D15:D18,"*차지"),D11,D10*IF(COUNTIF(D15,"*SG"),1+D67,1))) -> 10 | E9: =IF(OR(E8=0,E8=1),E10,0.5*IF(COUNTIF(E15:E18,"*차지"),E11,E10*IF(COUNTIF(E15,"*SG"),1+E67,1))) -> 15 | F9: =IF(OR(F8=0,F8=1),F10,0.5*IF(COUNTIF(F15:F18,"*차지"),F11,F10*IF(COUNTIF(F15,"*SG"),1+F67,1))) -> 15 | G9: =IF(OR(G8=0,G8=1),G10,0.5*IF(COUNTIF(G15:G18,"*차지"),G11,G10*IF(COUNTIF(G15,"*SG"),1+G67,1))) -> 0 | H9: =IF(OR(H8=0,H8=1),H10,0.5*IF(COUNTIF(H15:H18,"*차지"),H11,H10*IF(COUNTIF(H15,"*SG"),1+H67,1))) -> 0 | I9: =IF(OR(I8=0,I8=1),I10,0.5*IF(COUNTIF(I15:I18,"*차지"),I11,I10*IF(COUNTIF(I15,"*SG"),1+I67,1))) -> 15 | J9: =IF(OR(J8=0,J8=1),J10,0.5*IF(COUNTIF(J15:J18,"*차지"),J11,J10*IF(COUNTIF(J15,"*SG"),1+J67,1))) -> 15 | ... U9: =IF(OR(U8=0,U8=1),U10,0.5*IF(COUNTIF(U15:U18,"*차지"),U11,U10*IF(COUNTIF(U15,"*SG"),1+U67,1))) -> 0
B10: 횟수/발수(10초) | C10: {=INDEX(딜러데이터!$56:$56, 1, MATCH(메인!$F$4, 딜러데이터!$1:$1, 0)+C$8)} -> 10 | D10: {=INDEX(딜러데이터!$56:$56, 1, MATCH(메인!$F$4, 딜러데이터!$1:$1, 0)+D$8)} -> 10 | E10: {=INDEX(딜러데이터!$56:$56, 1, MATCH(메인!$F$4, 딜러데이터!$1:$1, 0)+E$8)} -> 30 | F10: {=INDEX(딜러데이터!$56:$56, 1, MATCH(메인!$F$4, 딜러데이터!$1:$1, 0)+F$8)} -> 30 | G10: {=INDEX(딜러데이터!$56:$56, 1, MATCH(메인!$F$4, 딜러데이터!$1:$1, 0)+G$8)} -> 0 | H10: {=INDEX(딜러데이터!$56:$56, 1, MATCH(메인!$F$4, 딜러데이터!$1:$1, 0)+H$8)} -> 0 | I10: {=INDEX(딜러데이터!$56:$56, 1, MATCH(메인!$F$4, 딜러데이터!$1:$1, 0)+I$8)} -> 30 | J10: {=INDEX(딜러데이터!$56:$56, 1, MATCH(메인!$F$4, 딜러데이터!$1:$1, 0)+J$8)} -> 30 | ... L10: {=INDEX(딜러데이터!$56:$56, 1, MATCH(메인!$F$4, 딜러데이터!$1:$1, 0)+L$8)} -> 0 | M10: {=INDEX(딜러데이터!$69:$69, 1, MATCH(메인!$F$4, 딜러데이터!$1:$1, 0)+M$8)} -> 0 | N10: {=INDEX(딜러데이터!$69:$69, 1, MATCH(메인!$F$4, 딜러데이터!$1:$1, 0)+N$8)} -> 30 | O10: {=INDEX(딜러데이터!$69:$69, 1, MATCH(메인!$F$4, 딜러데이터!$1:$1, 0)+O$8)} -> 30 | P10: {=INDEX(딜러데이터!$69:$69, 1, MATCH(메인!$F$4, 딜러데이터!$1:$1, 0)+P$8)} -> 0 | Q10: {=INDEX(딜러데이터!$69:$69, 1, MATCH(메인!$F$4, 딜러데이터!$1:$1, 0)+Q$8)} -> 0 | R10: {=INDEX(딜러데이터!$69:$69, 1, MATCH(메인!$F$4, 딜러데이터!$1:$1, 0)+R$8)} -> 30 | S10: {=INDEX(딜러데이터!$69:$69, 1, MATCH(메인!$F$4, 딜러데이터!$1:$1, 0)+S$8)} -> 30 | T10: {=INDEX(딜러데이터!$69:$69, 1, MATCH(메인!$F$4, 딜러데이터!$1:$1, 0)+T$8)} -> 0 | U10: {=INDEX(딜러데이터!$69:$69, 1, MATCH(메인!$F$4, 딜러데이터!$1:$1, 0)+U$8)} -> 0
B11: 횟수/발수(10초, 차지) | C11: =IF(메인!$C$13,10/(C12*(1-C13)+C14),C10) -> 10 | D11: =IF(메인!$C$13,10/(D12*(1-D13)+D14),D10) -> 10 | E11: =IF(메인!$C$13,10/(E12*(1-E13)+E14),E10) -> 30 | F11: =IF(메인!$C$13,10/(F12*(1-F13)+F14),F10) -> 30 | G11: =IF(메인!$C$13,10/(G12*(1-G13)+G14),G10) -> 0 | H11: =IF(메인!$C$13,10/(H12*(1-H13)+H14),H10) -> 0 | I11: =IF(메인!$C$13,10/(I12*(1-I13)+I14),I10) -> 30 | J11: =IF(메인!$C$13,10/(J12*(1-J13)+J14),J10) -> 30 | ... U11: =IF(메인!$C$13,10/(U12*(1-U13)+U14),U10) -> 0
B12: 기본차지시간 | C12: {=INDEX(딜러데이터!$58:$58, 1, MATCH(메인!$F$4, 딜러데이터!$1:$1, 0)+C$8)} -> 0 | D12: {=INDEX(딜러데이터!$58:$58, 1, MATCH(메인!$F$4, 딜러데이터!$1:$1, 0)+D$8)} -> 0 | E12: {=INDEX(딜러데이터!$58:$58, 1, MATCH(메인!$F$4, 딜러데이터!$1:$1, 0)+E$8)} -> 1 | F12: {=INDEX(딜러데이터!$58:$58, 1, MATCH(메인!$F$4, 딜러데이터!$1:$1, 0)+F$8)} -> 1 | G12: {=INDEX(딜러데이터!$58:$58, 1, MATCH(메인!$F$4, 딜러데이터!$1:$1, 0)+G$8)} -> 0 | H12: {=INDEX(딜러데이터!$58:$58, 1, MATCH(메인!$F$4, 딜러데이터!$1:$1, 0)+H$8)} -> 0 | I12: {=INDEX(딜러데이터!$58:$58, 1, MATCH(메인!$F$4, 딜러데이터!$1:$1, 0)+I$8)} -> 1 | J12: {=INDEX(딜러데이터!$58:$58, 1, MATCH(메인!$F$4, 딜러데이터!$1:$1, 0)+J$8)} -> 1 | ... L12: {=INDEX(딜러데이터!$58:$58, 1, MATCH(메인!$F$4, 딜러데이터!$1:$1, 0)+L$8)} -> 0 | M12: {=INDEX(딜러데이터!$71:$71, 1, MATCH(메인!$F$4, 딜러데이터!$1:$1, 0)+M$8)} -> 0 | N12: {=INDEX(딜러데이터!$71:$71, 1, MATCH(메인!$F$4, 딜러데이터!$1:$1, 0)+N$8)} -> 1 | O12: {=INDEX(딜러데이터!$71:$71, 1, MATCH(메인!$F$4, 딜러데이터!$1:$1, 0)+O$8)} -> 1 | P12: {=INDEX(딜러데이터!$71:$71, 1, MATCH(메인!$F$4, 딜러데이터!$1:$1, 0)+P$8)} -> 0 | Q12: {=INDEX(딜러데이터!$71:$71, 1, MATCH(메인!$F$4, 딜러데이터!$1:$1, 0)+Q$8)} -> 0 | R12: {=INDEX(딜러데이터!$71:$71, 1, MATCH(메인!$F$4, 딜러데이터!$1:$1, 0)+R$8)} -> 1 | S12: {=INDEX(딜러데이터!$71:$71, 1, MATCH(메인!$F$4, 딜러데이터!$1:$1, 0)+S$8)} -> 1 | T12: {=INDEX(딜러데이터!$71:$71, 1, MATCH(메인!$F$4, 딜러데이터!$1:$1, 0)+T$8)} -> 0 | U12: {=INDEX(딜러데이터!$71:$71, 1, MATCH(메인!$F$4, 딜러데이터!$1:$1, 0)+U$8)} -> 0
B13: 차지속도증가 | C13: =MIN(1,버프정리!$D$29+버프정리!$D$28/C12) -> #DIV/0! | D13: =MIN(1,버프정리!$D$29+버프정리!$D$28/D12) -> #DIV/0! | E13: =MIN(1,버프정리!$D$29+버프정리!$D$28/E12) -> 1 | F13: =MIN(1,버프정리!$D$29+버프정리!$D$28/F12) -> 1 | G13: =MIN(1,버프정리!$D$29+버프정리!$D$28/G12) -> #DIV/0! | H13: =MIN(1,버프정리!$D$29+버프정리!$D$28/H12) -> #DIV/0! | I13: =MIN(1,버프정리!$D$29+버프정리!$D$28/I12) -> 1 | J13: =MIN(1,버프정리!$D$29+버프정리!$D$28/J12) -> 1 | ... U13: =MIN(1,버프정리!$D$29+버프정리!$D$28/U12) -> #DIV/0!
B14: 딜레이 | C14: {=INDEX(딜러데이터!$59:$59, 1, MATCH(메인!$F$4, 딜러데이터!$1:$1, 0)+C$8)} -> 0 | D14: {=INDEX(딜러데이터!$59:$59, 1, MATCH(메인!$F$4, 딜러데이터!$1:$1, 0)+D$8)} -> 0 | E14: {=INDEX(딜러데이터!$59:$59, 1, MATCH(메인!$F$4, 딜러데이터!$1:$1, 0)+E$8)} -> 0.33 | F14: {=INDEX(딜러데이터!$59:$59, 1, MATCH(메인!$F$4, 딜러데이터!$1:$1, 0)+F$8)} -> 0.33 | G14: {=INDEX(딜러데이터!$59:$59, 1, MATCH(메인!$F$4, 딜러데이터!$1:$1, 0)+G$8)} -> 0 | H14: {=INDEX(딜러데이터!$59:$59, 1, MATCH(메인!$F$4, 딜러데이터!$1:$1, 0)+H$8)} -> 0 | I14: {=INDEX(딜러데이터!$59:$59, 1, MATCH(메인!$F$4, 딜러데이터!$1:$1, 0)+I$8)} -> 0.33 | J14: {=INDEX(딜러데이터!$59:$59, 1, MATCH(메인!$F$4, 딜러데이터!$1:$1, 0)+J$8)} -> 0.33 | ... L14: {=INDEX(딜러데이터!$59:$59, 1, MATCH(메인!$F$4, 딜러데이터!$1:$1, 0)+L$8)} -> 0 | M14: {=INDEX(딜러데이터!$72:$72, 1, MATCH(메인!$F$4, 딜러데이터!$1:$1, 0)+M$8)} -> 0 | N14: {=INDEX(딜러데이터!$72:$72, 1, MATCH(메인!$F$4, 딜러데이터!$1:$1, 0)+N$8)} -> 0.33 | O14: {=INDEX(딜러데이터!$72:$72, 1, MATCH(메인!$F$4, 딜러데이터!$1:$1, 0)+O$8)} -> 0.33 | P14: {=INDEX(딜러데이터!$72:$72, 1, MATCH(메인!$F$4, 딜러데이터!$1:$1, 0)+P$8)} -> 0 | Q14: {=INDEX(딜러데이터!$72:$72, 1, MATCH(메인!$F$4, 딜러데이터!$1:$1, 0)+Q$8)} -> 0 | R14: {=INDEX(딜러데이터!$72:$72, 1, MATCH(메인!$F$4, 딜러데이터!$1:$1, 0)+R$8)} -> 0.33 | S14: {=INDEX(딜러데이터!$72:$72, 1, MATCH(메인!$F$4, 딜러데이터!$1:$1, 0)+S$8)} -> 0.33 | T14: {=INDEX(딜러데이터!$72:$72, 1, MATCH(메인!$F$4, 딜러데이터!$1:$1, 0)+T$8)} -> 0 | U14: {=INDEX(딜러데이터!$72:$72, 1, MATCH(메인!$F$4, 딜러데이터!$1:$1, 0)+U$8)} -> 0
A15: 일반공격 첫줄 | B15: 대미지유형 | C15: {=INDEX(딜러데이터!62:62, 1, MATCH(메인!$F$4, 딜러데이터!$1:$1, 0)+C$8)} -> 스킬 | D15: {=INDEX(딜러데이터!62:62, 1, MATCH(메인!$F$4, 딜러데이터!$1:$1, 0)+D$8)} -> 스킬 | E15: {=INDEX(딜러데이터!62:62, 1, MATCH(메인!$F$4, 딜러데이터!$1:$1, 0)+E$8)} -> RL | F15: {=INDEX(딜러데이터!62:62, 1, MATCH(메인!$F$4, 딜러데이터!$1:$1, 0)+F$8)} -> 스킬 | G15: {=INDEX(딜러데이터!62:62, 1, MATCH(메인!$F$4, 딜러데이터!$1:$1, 0)+G$8)} -> 0 | H15: {=INDEX(딜러데이터!62:62, 1, MATCH(메인!$F$4, 딜러데이터!$1:$1, 0)+H$8)} -> 0 | I15: {=INDEX(딜러데이터!62:62, 1, MATCH(메인!$F$4, 딜러데이터!$1:$1, 0)+I$8)} -> RL | J15: {=INDEX(딜러데이터!62:62, 1, MATCH(메인!$F$4, 딜러데이터!$1:$1, 0)+J$8)} -> 스킬 | ... L15: {=INDEX(딜러데이터!62:62, 1, MATCH(메인!$F$4, 딜러데이터!$1:$1, 0)+L$8)} -> 0 | M15: {=INDEX(딜러데이터!75:75, 1, MATCH(메인!$F$4, 딜러데이터!$1:$1, 0)+M$8)} -> 0 | N15: {=INDEX(딜러데이터!75:75, 1, MATCH(메인!$F$4, 딜러데이터!$1:$1, 0)+N$8)} -> RL | O15: {=INDEX(딜러데이터!75:75, 1, MATCH(메인!$F$4, 딜러데이터!$1:$1, 0)+O$8)} -> 스킬 | P15: {=INDEX(딜러데이터!75:75, 1, MATCH(메인!$F$4, 딜러데이터!$1:$1, 0)+P$8)} -> 0 | Q15: {=INDEX(딜러데이터!75:75, 1, MATCH(메인!$F$4, 딜러데이터!$1:$1, 0)+Q$8)} -> 0 | R15: {=INDEX(딜러데이터!75:75, 1, MATCH(메인!$F$4, 딜러데이터!$1:$1, 0)+R$8)} -> RL | S15: {=INDEX(딜러데이터!75:75, 1, MATCH(메인!$F$4, 딜러데이터!$1:$1, 0)+S$8)} -> 스킬 | T15: {=INDEX(딜러데이터!75:75, 1, MATCH(메인!$F$4, 딜러데이터!$1:$1, 0)+T$8)} -> 0 | U15: {=INDEX(딜러데이터!75:75, 1, MATCH(메인!$F$4, 딜러데이터!$1:$1, 0)+U$8)} -> 0
A16: 차지/펠렛 둘째줄 | C16: {=INDEX(딜러데이터!63:63, 1, MATCH(메인!$F$4, 딜러데이터!$1:$1, 0)+C$8)} -> 0 | D16: {=INDEX(딜러데이터!63:63, 1, MATCH(메인!$F$4, 딜러데이터!$1:$1, 0)+D$8)} -> 0 | E16: {=INDEX(딜러데이터!63:63, 1, MATCH(메인!$F$4, 딜러데이터!$1:$1, 0)+E$8)} -> 차지 | F16: {=INDEX(딜러데이터!63:63, 1, MATCH(메인!$F$4, 딜러데이터!$1:$1, 0)+F$8)} -> 0 | G16: {=INDEX(딜러데이터!63:63, 1, MATCH(메인!$F$4, 딜러데이터!$1:$1, 0)+G$8)} -> 0 | H16: {=INDEX(딜러데이터!63:63, 1, MATCH(메인!$F$4, 딜러데이터!$1:$1, 0)+H$8)} -> 0 | I16: {=INDEX(딜러데이터!63:63, 1, MATCH(메인!$F$4, 딜러데이터!$1:$1, 0)+I$8)} -> 차지 | J16: {=INDEX(딜러데이터!63:63, 1, MATCH(메인!$F$4, 딜러데이터!$1:$1, 0)+J$8)} -> 0 | ... L16: {=INDEX(딜러데이터!63:63, 1, MATCH(메인!$F$4, 딜러데이터!$1:$1, 0)+L$8)} -> 0 | M16: {=INDEX(딜러데이터!76:76, 1, MATCH(메인!$F$4, 딜러데이터!$1:$1, 0)+M$8)} -> 0 | N16: {=INDEX(딜러데이터!76:76, 1, MATCH(메인!$F$4, 딜러데이터!$1:$1, 0)+N$8)} -> 차지 | O16: {=INDEX(딜러데이터!76:76, 1, MATCH(메인!$F$4, 딜러데이터!$1:$1, 0)+O$8)} -> 0 | P16: {=INDEX(딜러데이터!76:76, 1, MATCH(메인!$F$4, 딜러데이터!$1:$1, 0)+P$8)} -> 0 | Q16: {=INDEX(딜러데이터!76:76, 1, MATCH(메인!$F$4, 딜러데이터!$1:$1, 0)+Q$8)} -> 0 | R16: {=INDEX(딜러데이터!76:76, 1, MATCH(메인!$F$4, 딜러데이터!$1:$1, 0)+R$8)} -> 차지 | S16: {=INDEX(딜러데이터!76:76, 1, MATCH(메인!$F$4, 딜러데이터!$1:$1, 0)+S$8)} -> 0 | T16: {=INDEX(딜러데이터!76:76, 1, MATCH(메인!$F$4, 딜러데이터!$1:$1, 0)+T$8)} -> 0 | U16: {=INDEX(딜러데이터!76:76, 1, MATCH(메인!$F$4, 딜러데이터!$1:$1, 0)+U$8)} -> 0
C17: {=INDEX(딜러데이터!64:64, 1, MATCH(메인!$F$4, 딜러데이터!$1:$1, 0)+C$8)} -> 0 | D17: {=INDEX(딜러데이터!64:64, 1, MATCH(메인!$F$4, 딜러데이터!$1:$1, 0)+D$8)} -> 0 | E17: {=INDEX(딜러데이터!64:64, 1, MATCH(메인!$F$4, 딜러데이터!$1:$1, 0)+E$8)} -> 발사체폭발 | F17: {=INDEX(딜러데이터!64:64, 1, MATCH(메인!$F$4, 딜러데이터!$1:$1, 0)+F$8)} -> 0 | G17: {=INDEX(딜러데이터!64:64, 1, MATCH(메인!$F$4, 딜러데이터!$1:$1, 0)+G$8)} -> 0 | H17: {=INDEX(딜러데이터!64:64, 1, MATCH(메인!$F$4, 딜러데이터!$1:$1, 0)+H$8)} -> 0 | I17: {=INDEX(딜러데이터!64:64, 1, MATCH(메인!$F$4, 딜러데이터!$1:$1, 0)+I$8)} -> 발사체폭발 | J17: {=INDEX(딜러데이터!64:64, 1, MATCH(메인!$F$4, 딜러데이터!$1:$1, 0)+J$8)} -> 0 | ... L17: {=INDEX(딜러데이터!64:64, 1, MATCH(메인!$F$4, 딜러데이터!$1:$1, 0)+L$8)} -> 0 | M17: {=INDEX(딜러데이터!77:77, 1, MATCH(메인!$F$4, 딜러데이터!$1:$1, 0)+M$8)} -> 0 | N17: {=INDEX(딜러데이터!77:77, 1, MATCH(메인!$F$4, 딜러데이터!$1:$1, 0)+N$8)} -> 발사체폭발 | O17: {=INDEX(딜러데이터!77:77, 1, MATCH(메인!$F$4, 딜러데이터!$1:$1, 0)+O$8)} -> 0 | P17: {=INDEX(딜러데이터!77:77, 1, MATCH(메인!$F$4, 딜러데이터!$1:$1, 0)+P$8)} -> 0 | Q17: {=INDEX(딜러데이터!77:77, 1, MATCH(메인!$F$4, 딜러데이터!$1:$1, 0)+Q$8)} -> 0 | R17: {=INDEX(딜러데이터!77:77, 1, MATCH(메인!$F$4, 딜러데이터!$1:$1, 0)+R$8)} -> 발사체폭발 | S17: {=INDEX(딜러데이터!77:77, 1, MATCH(메인!$F$4, 딜러데이터!$1:$1, 0)+S$8)} -> 0 | T17: {=INDEX(딜러데이터!77:77, 1, MATCH(메인!$F$4, 딜러데이터!$1:$1, 0)+T$8)} -> 0 | U17: {=INDEX(딜러데이터!77:77, 1, MATCH(메인!$F$4, 딜러데이터!$1:$1, 0)+U$8)} -> 0
C18: {=INDEX(딜러데이터!65:65, 1, MATCH(메인!$F$4, 딜러데이터!$1:$1, 0)+C$8)} -> 0 | D18: {=INDEX(딜러데이터!65:65, 1, MATCH(메인!$F$4, 딜러데이터!$1:$1, 0)+D$8)} -> 0 | E18: {=INDEX(딜러데이터!65:65, 1, MATCH(메인!$F$4, 딜러데이터!$1:$1, 0)+E$8)} -> 0 | F18: {=INDEX(딜러데이터!65:65, 1, MATCH(메인!$F$4, 딜러데이터!$1:$1, 0)+F$8)} -> 풀차지 | G18: {=INDEX(딜러데이터!65:65, 1, MATCH(메인!$F$4, 딜러데이터!$1:$1, 0)+G$8)} -> 0 | H18: {=INDEX(딜러데이터!65:65, 1, MATCH(메인!$F$4, 딜러데이터!$1:$1, 0)+H$8)} -> 0 | I18: {=INDEX(딜러데이터!65:65, 1, MATCH(메인!$F$4, 딜러데이터!$1:$1, 0)+I$8)} -> 0 | J18: {=INDEX(딜러데이터!65:65, 1, MATCH(메인!$F$4, 딜러데이터!$1:$1, 0)+J$8)} -> 풀차지 | ... L18: {=INDEX(딜러데이터!65:65, 1, MATCH(메인!$F$4, 딜러데이터!$1:$1, 0)+L$8)} -> 0 | M18: {=INDEX(딜러데이터!78:78, 1, MATCH(메인!$F$4, 딜러데이터!$1:$1, 0)+M$8)} -> 0 | N18: {=INDEX(딜러데이터!78:78, 1, MATCH(메인!$F$4, 딜러데이터!$1:$1, 0)+N$8)} -> 0 | O18: {=INDEX(딜러데이터!78:78, 1, MATCH(메인!$F$4, 딜러데이터!$1:$1, 0)+O$8)} -> 풀차지 | P18: {=INDEX(딜러데이터!78:78, 1, MATCH(메인!$F$4, 딜러데이터!$1:$1, 0)+P$8)} -> 0 | Q18: {=INDEX(딜러데이터!78:78, 1, MATCH(메인!$F$4, 딜러데이터!$1:$1, 0)+Q$8)} -> 0 | R18: {=INDEX(딜러데이터!78:78, 1, MATCH(메인!$F$4, 딜러데이터!$1:$1, 0)+R$8)} -> 0 | S18: {=INDEX(딜러데이터!78:78, 1, MATCH(메인!$F$4, 딜러데이터!$1:$1, 0)+S$8)} -> 풀차지 | T18: {=INDEX(딜러데이터!78:78, 1, MATCH(메인!$F$4, 딜러데이터!$1:$1, 0)+T$8)} -> 0 | U18: {=INDEX(딜러데이터!78:78, 1, MATCH(메인!$F$4, 딜러데이터!$1:$1, 0)+U$8)} -> 0
B19: 평균한발대미지 | C19: =MAX(1,PRODUCT(C21:C25)*IF(COUNTIF(니케스팩!$M:$M, C15), C26, C28)*IF(C16="차지", C29, 1)) -> 7005209.3 | D19: =MAX(1,PRODUCT(D21:D25)*IF(COUNTIF(니케스팩!$M:$M, D15), D26, D28)*IF(D16="차지", D29, 1)) -> 3478577.9 | E19: =MAX(1,PRODUCT(E21:E25)*IF(COUNTIF(니케스팩!$M:$M, E15), E26, E28)*IF(E16="차지", E29, 1)) -> 1140586.9 | F19: =MAX(1,PRODUCT(F21:F25)*IF(COUNTIF(니케스팩!$M:$M, F15), F26, F28)*IF(F16="차지", F29, 1)) -> 1370166.5 | G19: =MAX(1,PRODUCT(G21:G25)*IF(COUNTIF(니케스팩!$M:$M, G15), G26, G28)*IF(G16="차지", G29, 1)) -> 1 | H19: =MAX(1,PRODUCT(H21:H25)*IF(COUNTIF(니케스팩!$M:$M, H15), H26, H28)*IF(H16="차지", H29, 1)) -> 1 | I19: =MAX(1,PRODUCT(I21:I25)*IF(COUNTIF(니케스팩!$M:$M, I15), I26, I28)*IF(I16="차지", I29, 1)) -> 1022223.2 | J19: =MAX(1,PRODUCT(J21:J25)*IF(COUNTIF(니케스팩!$M:$M, J15), J26, J28)*IF(J16="차지", J29, 1)) -> 1227978.3 | ... U19: =MAX(1,PRODUCT(U21:U25)*IF(COUNTIF(니케스팩!$M:$M, U15), U26, U28)*IF(U16="차지", U29, 1)) -> 1
A20: 계산에는 사용 안 함 | B20: 한발대미지(노크리) | C20: =PRODUCT(C21:C25)*IF(C16="차지", C29, 1)*(1+IF(C8,0.5,0)+IF(COUNTIF(니케스팩!$M:$M, C15),IF(메인!$C$4,메인!$C$4+C54+IF(AND(COUNTIF(C15:C18,"관통"),메인!$C$5),1,0),0)+IF(메인!$C$8,0.3+C55,0),0)) -> 5324765.5 | D20: =PRODUCT(D21:D25)*IF(D16="차지", D29, 1)*(1+IF(D8,0.5,0)+IF(COUNTIF(니케스팩!$M:$M, D15),IF(메인!$C$4,메인!$C$4+D54+IF(AND(COUNTIF(D15:D18,"관통"),메인!$C$5),1,0),0)+IF(메인!$C$8,0.3+D55,0),0)) -> 2873923.2 | E20: =PRODUCT(E21:E25)*IF(E16="차지", E29, 1)*(1+IF(E8,0.5,0)+IF(COUNTIF(니케스팩!$M:$M, E15),IF(메인!$C$4,메인!$C$4+E54+IF(AND(COUNTIF(E15:E18,"관통"),메인!$C$5),1,0),0)+IF(메인!$C$8,0.3+E55,0),0)) -> 942327.39 | F20: =PRODUCT(F21:F25)*IF(F16="차지", F29, 1)*(1+IF(F8,0.5,0)+IF(COUNTIF(니케스팩!$M:$M, F15),IF(메인!$C$4,메인!$C$4+F54+IF(AND(COUNTIF(F15:F18,"관통"),메인!$C$5),1,0),0)+IF(메인!$C$8,0.3+F55,0),0)) -> 1132000.9 | G20: =PRODUCT(G21:G25)*IF(G16="차지", G29, 1)*(1+IF(G8,0.5,0)+IF(COUNTIF(니케스팩!$M:$M, G15),IF(메인!$C$4,메인!$C$4+G54+IF(AND(COUNTIF(G15:G18,"관통"),메인!$C$5),1,0),0)+IF(메인!$C$8,0.3+G55,0),0)) -> 0 | H20: =PRODUCT(H21:H25)*IF(H16="차지", H29, 1)*(1+IF(H8,0.5,0)+IF(COUNTIF(니케스팩!$M:$M, H15),IF(메인!$C$4,메인!$C$4+H54+IF(AND(COUNTIF(H15:H18,"관통"),메인!$C$5),1,0),0)+IF(메인!$C$8,0.3+H55,0),0)) -> 0 | I20: =PRODUCT(I21:I25)*IF(I16="차지", I29, 1)*(1+IF(I8,0.5,0)+IF(COUNTIF(니케스팩!$M:$M, I15),IF(메인!$C$4,메인!$C$4+I54+IF(AND(COUNTIF(I15:I18,"관통"),메인!$C$5),1,0),0)+IF(메인!$C$8,0.3+I55,0),0)) -> 844537.96 | J20: =PRODUCT(J21:J25)*IF(J16="차지", J29, 1)*(1+IF(J8,0.5,0)+IF(COUNTIF(니케스팩!$M:$M, J15),IF(메인!$C$4,메인!$C$4+J54+IF(AND(COUNTIF(J15:J18,"관통"),메인!$C$5),1,0),0)+IF(메인!$C$8,0.3+J55,0),0)) -> 1014528.2 | ... U20: =PRODUCT(U21:U25)*IF(U16="차지", U29, 1)*(1+IF(U8,0.5,0)+IF(COUNTIF(니케스팩!$M:$M, U15),IF(메인!$C$4,메인!$C$4+U54+IF(AND(COUNTIF(U15:U18,"관통"),메인!$C$5),1,0),0)+IF(메인!$C$8,0.3+U55,0),0)) -> 0
B21: 계수 | C21: {=INDEX(딜러데이터!$55:$55, 1, MATCH(메인!$F$4, 딜러데이터!$1:$1, 0)+C$8)*(1+C60)} -> 13.6592 | D21: {=INDEX(딜러데이터!$55:$55, 1, MATCH(메인!$F$4, 딜러데이터!$1:$1, 0)+D$8)*(1+D60)} -> 3.468 | E21: {=INDEX(딜러데이터!$55:$55, 1, MATCH(메인!$F$4, 딜러데이터!$1:$1, 0)+E$8)*(1+E60)} -> 0.3211 | F21: {=INDEX(딜러데이터!$55:$55, 1, MATCH(메인!$F$4, 딜러데이터!$1:$1, 0)+F$8)*(1+F60)} -> 1.366 | G21: {=INDEX(딜러데이터!$55:$55, 1, MATCH(메인!$F$4, 딜러데이터!$1:$1, 0)+G$8)*(1+G60)} -> 0 | H21: {=INDEX(딜러데이터!$55:$55, 1, MATCH(메인!$F$4, 딜러데이터!$1:$1, 0)+H$8)*(1+H60)} -> 0 | I21: {=INDEX(딜러데이터!$55:$55, 1, MATCH(메인!$F$4, 딜러데이터!$1:$1, 0)+I$8)*(1+I60)} -> 0.3211 | J21: {=INDEX(딜러데이터!$55:$55, 1, MATCH(메인!$F$4, 딜러데이터!$1:$1, 0)+J$8)*(1+J60)} -> 1.366 | ... L21: {=INDEX(딜러데이터!$55:$55, 1, MATCH(메인!$F$4, 딜러데이터!$1:$1, 0)+L$8)*(1+L60)} -> 0 | M21: {=INDEX(딜러데이터!$68:$68, 1, MATCH(메인!$F$4, 딜러데이터!$1:$1, 0)+M$8)*(1+M60)} -> 0 | N21: {=INDEX(딜러데이터!$68:$68, 1, MATCH(메인!$F$4, 딜러데이터!$1:$1, 0)+N$8)*(1+N60)} -> 0.3211 | O21: {=INDEX(딜러데이터!$68:$68, 1, MATCH(메인!$F$4, 딜러데이터!$1:$1, 0)+O$8)*(1+O60)} -> 1.366 | P21: {=INDEX(딜러데이터!$68:$68, 1, MATCH(메인!$F$4, 딜러데이터!$1:$1, 0)+P$8)*(1+P60)} -> 0 | Q21: {=INDEX(딜러데이터!$68:$68, 1, MATCH(메인!$F$4, 딜러데이터!$1:$1, 0)+Q$8)*(1+Q60)} -> 0 | R21: {=INDEX(딜러데이터!$68:$68, 1, MATCH(메인!$F$4, 딜러데이터!$1:$1, 0)+R$8)*(1+R60)} -> 0.3211 | S21: {=INDEX(딜러데이터!$68:$68, 1, MATCH(메인!$F$4, 딜러데이터!$1:$1, 0)+S$8)*(1+S60)} -> 1.366 | T21: {=INDEX(딜러데이터!$68:$68, 1, MATCH(메인!$F$4, 딜러데이터!$1:$1, 0)+T$8)*(1+T60)} -> 0 | U21: {=INDEX(딜러데이터!$68:$68, 1, MATCH(메인!$F$4, 딜러데이터!$1:$1, 0)+U$8)*(1+U60)} -> 0
A22: 아래는스킬별구분하는이유 | B22: 우월코드대미지 | C22: =IF(메인!$C$9,1.1+C59,1) -> 1 | D22: =IF(메인!$C$9,1.1+D59,1) -> 1 | E22: =IF(메인!$C$9,1.1+E59,1) -> 1 | F22: =IF(메인!$C$9,1.1+F59,1) -> 1 | G22: =IF(메인!$C$9,1.1+G59,1) -> 1 | H22: =IF(메인!$C$9,1.1+H59,1) -> 1 | I22: =IF(메인!$C$9,1.1+I59,1) -> 1 | J22: =IF(메인!$C$9,1.1+J59,1) -> 1 | ... U22: =IF(메인!$C$9,1.1+U59,1) -> 1
A23: 방무구분 | B23: 공격력-방어력 | C23: =메인!$F$7*(1+C36)+C33-IF(COUNTIF(C15:C18, "방어력무시"), 0, 메인!$C$3*(1-MIN(1,C37))) -> 338864.71 | D23: =메인!$F$7*(1+D36)+D33-IF(COUNTIF(D15:D18, "방어력무시"), 0, 메인!$C$3*(1-MIN(1,D37))) -> 370682.4 | E23: =메인!$F$7*(1+E36)+E33-IF(COUNTIF(E15:E18, "방어력무시"), 0, 메인!$C$3*(1-MIN(1,E37))) -> 370682.4 | F23: =메인!$F$7*(1+F36)+F33-IF(COUNTIF(F15:F18, "방어력무시"), 0, 메인!$C$3*(1-MIN(1,F37))) -> 370682.4 | G23: =메인!$F$7*(1+G36)+G33-IF(COUNTIF(G15:G18, "방어력무시"), 0, 메인!$C$3*(1-MIN(1,G37))) -> 370682.4 | H23: =메인!$F$7*(1+H36)+H33-IF(COUNTIF(H15:H18, "방어력무시"), 0, 메인!$C$3*(1-MIN(1,H37))) -> 370682.4 | I23: =메인!$F$7*(1+I36)+I33-IF(COUNTIF(I15:I18, "방어력무시"), 0, 메인!$C$3*(1-MIN(1,I37))) -> 332215.07 | J23: =메인!$F$7*(1+J36)+J33-IF(COUNTIF(J15:J18, "방어력무시"), 0, 메인!$C$3*(1-MIN(1,J37))) -> 332215.07 | ... U23: =메인!$F$7*(1+U36)+U33-IF(COUNTIF(U15:U18, "방어력무시"), 0, 메인!$C$3*(1-MIN(1,U37))) -> 299163.04
A24: 유형별구분 | B24: 공격유형별버프 | C24: {=1+C38+IFERROR(SUM(_xlfn._xlws.FILTER(C39:C47, ISNUMBER(MATCH($B39:$B47, C15:C18, 0)))),0)} -> 1.1504 | D24: {=1+D38+IFERROR(SUM(_xlfn._xlws.FILTER(D39:D47, ISNUMBER(MATCH($B39:$B47, D15:D18, 0)))),0)} -> 1.4904 | E24: {=1+E38+IFERROR(SUM(_xlfn._xlws.FILTER(E39:E47, ISNUMBER(MATCH($B39:$B47, E15:E18, 0)))),0)} -> 2.4107 | F24: {=1+F38+IFERROR(SUM(_xlfn._xlws.FILTER(F39:F47, ISNUMBER(MATCH($B39:$B47, F15:F18, 0)))),0)} -> 1.4904 | G24: {=1+G38+IFERROR(SUM(_xlfn._xlws.FILTER(G39:G47, ISNUMBER(MATCH($B39:$B47, G15:G18, 0)))),0)} -> 1.4904 | H24: {=1+H38+IFERROR(SUM(_xlfn._xlws.FILTER(H39:H47, ISNUMBER(MATCH($B39:$B47, H15:H18, 0)))),0)} -> 1.4904 | I24: {=1+I38+IFERROR(SUM(_xlfn._xlws.FILTER(I39:I47, ISNUMBER(MATCH($B39:$B47, I15:I18, 0)))),0)} -> 2.4107 | J24: {=1+J38+IFERROR(SUM(_xlfn._xlws.FILTER(J39:J47, ISNUMBER(MATCH($B39:$B47, J15:J18, 0)))),0)} -> 1.4904 | ... U24: {=1+U38+IFERROR(SUM(_xlfn._xlws.FILTER(U39:U47, ISNUMBER(MATCH($B39:$B47, U15:U18, 0)))),0)} -> 1.34
A25: 분배구분 | B25: 적받는대미지 | C25: =1+C49+IF(COUNTIF(C15:C18, "분배"), C48, 0) -> 1 | D25: =1+D49+IF(COUNTIF(D15:D18, "분배"), D48, 0) -> 1 | E25: =1+E49+IF(COUNTIF(E15:E18, "분배"), E48, 0) -> 1 | F25: =1+F49+IF(COUNTIF(F15:F18, "분배"), F48, 0) -> 1 | G25: =1+G49+IF(COUNTIF(G15:G18, "분배"), G48, 0) -> 1 | H25: =1+H49+IF(COUNTIF(H15:H18, "분배"), H48, 0) -> 1 | I25: =1+I49+IF(COUNTIF(I15:I18, "분배"), I48, 0) -> 1 | J25: =1+J49+IF(COUNTIF(J15:J18, "분배"), J48, 0) -> 1 | ... U25: =1+U49+IF(COUNTIF(U15:U18, "분배"), U48, 0) -> 1
A26: 추후평타마다코어적중확률다른것다룰수있으니구분 | B26: 대미지증가계수(일반공격) | C26: =1+IF(C8,0.5,0)+(0.15+MIN(1,SUM(C50:C51)))*(0.5+SUM(C52:C53))+IF(메인!$C$4,메인!$C$4+C54+IF(AND(COUNTIF(C15:C18,"관통"),메인!$C$5),1,0),0)*C27+IF(메인!$C$8,0.3+C55,0) -> #N/A | D26: =1+IF(D8,0.5,0)+(0.15+MIN(1,SUM(D50:D51)))*(0.5+SUM(D52:D53))+IF(메인!$C$4,메인!$C$4+D54+IF(AND(COUNTIF(D15:D18,"관통"),메인!$C$5),1,0),0)*D27+IF(메인!$C$8,0.3+D55,0) -> #N/A | E26: =1+IF(E8,0.5,0)+(0.15+MIN(1,SUM(E50:E51)))*(0.5+SUM(E52:E53))+IF(메인!$C$4,메인!$C$4+E54+IF(AND(COUNTIF(E15:E18,"관통"),메인!$C$5),1,0),0)*E27+IF(메인!$C$8,0.3+E55,0) -> 1.8155902 | F26: =1+IF(F8,0.5,0)+(0.15+MIN(1,SUM(F50:F51)))*(0.5+SUM(F52:F53))+IF(메인!$C$4,메인!$C$4+F54+IF(AND(COUNTIF(F15:F18,"관통"),메인!$C$5),1,0),0)*F27+IF(메인!$C$8,0.3+F55,0) -> #N/A | G26: =1+IF(G8,0.5,0)+(0.15+MIN(1,SUM(G50:G51)))*(0.5+SUM(G52:G53))+IF(메인!$C$4,메인!$C$4+G54+IF(AND(COUNTIF(G15:G18,"관통"),메인!$C$5),1,0),0)*G27+IF(메인!$C$8,0.3+G55,0) -> #N/A | H26: =1+IF(H8,0.5,0)+(0.15+MIN(1,SUM(H50:H51)))*(0.5+SUM(H52:H53))+IF(메인!$C$4,메인!$C$4+H54+IF(AND(COUNTIF(H15:H18,"관통"),메인!$C$5),1,0),0)*H27+IF(메인!$C$8,0.3+H55,0) -> #N/A | I26: =1+IF(I8,0.5,0)+(0.15+MIN(1,SUM(I50:I51)))*(0.5+SUM(I52:I53))+IF(메인!$C$4,메인!$C$4+I54+IF(AND(COUNTIF(I15:I18,"관통"),메인!$C$5),1,0),0)*I27+IF(메인!$C$8,0.3+I55,0) -> 1.8155902 | J26: =1+IF(J8,0.5,0)+(0.15+MIN(1,SUM(J50:J51)))*(0.5+SUM(J52:J53))+IF(메인!$C$4,메인!$C$4+J54+IF(AND(COUNTIF(J15:J18,"관통"),메인!$C$5),1,0),0)*J27+IF(메인!$C$8,0.3+J55,0) -> #N/A | ... U26: =1+IF(U8,0.5,0)+(0.15+MIN(1,SUM(U50:U51)))*(0.5+SUM(U52:U53))+IF(메인!$C$4,메인!$C$4+U54+IF(AND(COUNTIF(U15:U18,"관통"),메인!$C$5),1,0),0)*U27+IF(메인!$C$8,0.3+U55,0) -> #N/A
B27: 코어히트율 | C27: =IF(ISBLANK(메인!$C$7),(메인!$C$6/MAX(메인!$C$6,VLOOKUP(C15,니케스팩!$M:$P,COLUMN(니케스팩!$P$1)-COLUMN(니케스팩!$M$1)+1,0)*(1-C69/1.15)))^2,메인!$C$7) -> #N/A | D27: =IF(ISBLANK(메인!$C$7),(메인!$C$6/MAX(메인!$C$6,VLOOKUP(D15,니케스팩!$M:$P,COLUMN(니케스팩!$P$1)-COLUMN(니케스팩!$M$1)+1,0)*(1-D69/1.15)))^2,메인!$C$7) -> #N/A | E27: =IF(ISBLANK(메인!$C$7),(메인!$C$6/MAX(메인!$C$6,VLOOKUP(E15,니케스팩!$M:$P,COLUMN(니케스팩!$P$1)-COLUMN(니케스팩!$M$1)+1,0)*(1-E69/1.15)))^2,메인!$C$7) -> 1 | F27: =IF(ISBLANK(메인!$C$7),(메인!$C$6/MAX(메인!$C$6,VLOOKUP(F15,니케스팩!$M:$P,COLUMN(니케스팩!$P$1)-COLUMN(니케스팩!$M$1)+1,0)*(1-F69/1.15)))^2,메인!$C$7) -> #N/A | G27: =IF(ISBLANK(메인!$C$7),(메인!$C$6/MAX(메인!$C$6,VLOOKUP(G15,니케스팩!$M:$P,COLUMN(니케스팩!$P$1)-COLUMN(니케스팩!$M$1)+1,0)*(1-G69/1.15)))^2,메인!$C$7) -> #N/A | H27: =IF(ISBLANK(메인!$C$7),(메인!$C$6/MAX(메인!$C$6,VLOOKUP(H15,니케스팩!$M:$P,COLUMN(니케스팩!$P$1)-COLUMN(니케스팩!$M$1)+1,0)*(1-H69/1.15)))^2,메인!$C$7) -> #N/A | I27: =IF(ISBLANK(메인!$C$7),(메인!$C$6/MAX(메인!$C$6,VLOOKUP(I15,니케스팩!$M:$P,COLUMN(니케스팩!$P$1)-COLUMN(니케스팩!$M$1)+1,0)*(1-I69/1.15)))^2,메인!$C$7) -> 1 | J27: =IF(ISBLANK(메인!$C$7),(메인!$C$6/MAX(메인!$C$6,VLOOKUP(J15,니케스팩!$M:$P,COLUMN(니케스팩!$P$1)-COLUMN(니케스팩!$M$1)+1,0)*(1-J69/1.15)))^2,메인!$C$7) -> #N/A | ... U27: =IF(ISBLANK(메인!$C$7),(메인!$C$6/MAX(메인!$C$6,VLOOKUP(U15,니케스팩!$M:$P,COLUMN(니케스팩!$P$1)-COLUMN(니케스팩!$M$1)+1,0)*(1-U69/1.15)))^2,메인!$C$7) -> #N/A
B28: 대미지증가계수(스킬) | C28: =1+IF(C8,0.5,0)+(0.15+MIN(1,C50))*(0.5+C52) -> 1.3155902 | D28: =1+IF(D8,0.5,0)+(0.15+MIN(1,D50))*(0.5+D52) -> 1.8155902 | E28: =1+IF(E8,0.5,0)+(0.15+MIN(1,E50))*(0.5+E52) -> 1.8155902 | F28: =1+IF(F8,0.5,0)+(0.15+MIN(1,F50))*(0.5+F52) -> 1.8155902 | G28: =1+IF(G8,0.5,0)+(0.15+MIN(1,G50))*(0.5+G52) -> 1.8155902 | H28: =1+IF(H8,0.5,0)+(0.15+MIN(1,H50))*(0.5+H52) -> 1.8155902 | I28: =1+IF(I8,0.5,0)+(0.15+MIN(1,I50))*(0.5+I52) -> 1.8155902 | J28: =1+IF(J8,0.5,0)+(0.15+MIN(1,J50))*(0.5+J52) -> 1.8155902 | ... U28: =1+IF(U8,0.5,0)+(0.15+MIN(1,U50))*(0.5+U52) -> 1.67525
A29: 평타별차댐구분 | B29: 차지대미지 | C29: =C30+C56 -> 0 | D29: =D30+D56 -> 0 | E29: =E30+E56 -> 2.1894 | F29: =F30+F56 -> 2.1894 | G29: =G30+G56 -> 0 | H29: =H30+H56 -> 0 | I29: =I30+I56 -> 2.1894 | J29: =J30+J56 -> 2.1894 | ... U29: =U30+U56 -> 0
B30: 기본차지대미지 | C30: {=INDEX(딜러데이터!$57:$57, 1, MATCH(메인!$F$4, 딜러데이터!$1:$1, 0)+C$8)*(1+IF(OR(메인!$F$6="SR",메인!$F$6="RL"),9.47%,0))} -> 0 | D30: {=INDEX(딜러데이터!$57:$57, 1, MATCH(메인!$F$4, 딜러데이터!$1:$1, 0)+D$8)*(1+IF(OR(메인!$F$6="SR",메인!$F$6="RL"),9.47%,0))} -> 0 | E30: {=INDEX(딜러데이터!$57:$57, 1, MATCH(메인!$F$4, 딜러데이터!$1:$1, 0)+E$8)*(1+IF(OR(메인!$F$6="SR",메인!$F$6="RL"),9.47%,0))} -> 2.1894 | F30: {=INDEX(딜러데이터!$57:$57, 1, MATCH(메인!$F$4, 딜러데이터!$1:$1, 0)+F$8)*(1+IF(OR(메인!$F$6="SR",메인!$F$6="RL"),9.47%,0))} -> 2.1894 | G30: {=INDEX(딜러데이터!$57:$57, 1, MATCH(메인!$F$4, 딜러데이터!$1:$1, 0)+G$8)*(1+IF(OR(메인!$F$6="SR",메인!$F$6="RL"),9.47%,0))} -> 0 | H30: {=INDEX(딜러데이터!$57:$57, 1, MATCH(메인!$F$4, 딜러데이터!$1:$1, 0)+H$8)*(1+IF(OR(메인!$F$6="SR",메인!$F$6="RL"),9.47%,0))} -> 0 | I30: {=INDEX(딜러데이터!$57:$57, 1, MATCH(메인!$F$4, 딜러데이터!$1:$1, 0)+I$8)*(1+IF(OR(메인!$F$6="SR",메인!$F$6="RL"),9.47%,0))} -> 2.1894 | J30: {=INDEX(딜러데이터!$57:$57, 1, MATCH(메인!$F$4, 딜러데이터!$1:$1, 0)+J$8)*(1+IF(OR(메인!$F$6="SR",메인!$F$6="RL"),9.47%,0))} -> 2.1894 | ... L30: {=INDEX(딜러데이터!$57:$57, 1, MATCH(메인!$F$4, 딜러데이터!$1:$1, 0)+L$8)*(1+IF(OR(메인!$F$6="SR",메인!$F$6="RL"),9.47%,0))} -> 0 | M30: {=INDEX(딜러데이터!$70:$70, 1, MATCH(메인!$F$4, 딜러데이터!$1:$1, 0)+M$8)*(1+IF(OR(메인!$F$6="SR",메인!$F$6="RL"),9.47%,0))} -> 0 | N30: {=INDEX(딜러데이터!$70:$70, 1, MATCH(메인!$F$4, 딜러데이터!$1:$1, 0)+N$8)*(1+IF(OR(메인!$F$6="SR",메인!$F$6="RL"),9.47%,0))} -> 2.1894 | O30: {=INDEX(딜러데이터!$70:$70, 1, MATCH(메인!$F$4, 딜러데이터!$1:$1, 0)+O$8)*(1+IF(OR(메인!$F$6="SR",메인!$F$6="RL"),9.47%,0))} -> 2.1894 | P30: {=INDEX(딜러데이터!$70:$70, 1, MATCH(메인!$F$4, 딜러데이터!$1:$1, 0)+P$8)*(1+IF(OR(메인!$F$6="SR",메인!$F$6="RL"),9.47%,0))} -> 0 | Q30: {=INDEX(딜러데이터!$70:$70, 1, MATCH(메인!$F$4, 딜러데이터!$1:$1, 0)+Q$8)*(1+IF(OR(메인!$F$6="SR",메인!$F$6="RL"),9.47%,0))} -> 0 | R30: {=INDEX(딜러데이터!$70:$70, 1, MATCH(메인!$F$4, 딜러데이터!$1:$1, 0)+R$8)*(1+IF(OR(메인!$F$6="SR",메인!$F$6="RL"),9.47%,0))} -> 2.1894 | S30: {=INDEX(딜러데이터!$70:$70, 1, MATCH(메인!$F$4, 딜러데이터!$1:$1, 0)+S$8)*(1+IF(OR(메인!$F$6="SR",메인!$F$6="RL"),9.47%,0))} -> 2.1894 | T30: {=INDEX(딜러데이터!$70:$70, 1, MATCH(메인!$F$4, 딜러데이터!$1:$1, 0)+T$8)*(1+IF(OR(메인!$F$6="SR",메인!$F$6="RL"),9.47%,0))} -> 0 | U30: {=INDEX(딜러데이터!$70:$70, 1, MATCH(메인!$F$4, 딜러데이터!$1:$1, 0)+U$8)*(1+IF(OR(메인!$F$6="SR",메인!$F$6="RL"),9.47%,0))} -> 0
A33: 시전자기준 | B33: 서포터기준공격력 | C33: =버프정리!$D4 -> 143038.73 | D33: =버프정리!$J4 -> 174856.42 | E33: =버프정리!$J4 -> 174856.42 | F33: =버프정리!$J4 -> 174856.42 | G33: =버프정리!$J4 -> 174856.42 | H33: =버프정리!$J4 -> 174856.42 | I33: =버프정리!$P4 -> 136389.08 | J33: =버프정리!$P4 -> 136389.08 | K33: =버프정리!$P4 -> 136389.08 | L33: =버프정리!$P4 -> 136389.08 | M33: =버프정리!$V4 -> 76934.668 | N33: =버프정리!$AB4 -> 141804.39 | O33: =버프정리!$AB4 -> 141804.39 | P33: =버프정리!$AB4 -> 141804.39 | Q33: =버프정리!$AB4 -> 141804.39 | R33: =버프정리!$AH4 -> 103337.05 | S33: =버프정리!$AH4 -> 103337.05 | T33: =버프정리!$AH4 -> 103337.05 | U33: =버프정리!$AH4 -> 103337.05
B34: 서포터기준체력(만) | C34: =버프정리!$D5 -> 0 | D34: =버프정리!$J5 -> 0 | E34: =버프정리!$J5 -> 0 | F34: =버프정리!$J5 -> 0 | G34: =버프정리!$J5 -> 0 | H34: =버프정리!$J5 -> 0 | I34: =버프정리!$P5 -> 0 | J34: =버프정리!$P5 -> 0 | K34: =버프정리!$P5 -> 0 | L34: =버프정리!$P5 -> 0 | M34: =버프정리!$V5 -> 0 | N34: =버프정리!$AB5 -> 0 | O34: =버프정리!$AB5 -> 0 | P34: =버프정리!$AB5 -> 0 | Q34: =버프정리!$AB5 -> 0 | R34: =버프정리!$AH5 -> 0 | S34: =버프정리!$AH5 -> 0 | T34: =버프정리!$AH5 -> 0 | U34: =버프정리!$AH5 -> 0
B35: 서포터기준방어력 | C35: =버프정리!$D6 -> 0 | D35: =버프정리!$J6 -> 0 | E35: =버프정리!$J6 -> 0 | F35: =버프정리!$J6 -> 0 | G35: =버프정리!$J6 -> 0 | H35: =버프정리!$J6 -> 0 | I35: =버프정리!$P6 -> 0 | J35: =버프정리!$P6 -> 0 | K35: =버프정리!$P6 -> 0 | L35: =버프정리!$P6 -> 0 | M35: =버프정리!$V6 -> 0 | N35: =버프정리!$AB6 -> 0 | O35: =버프정리!$AB6 -> 0 | P35: =버프정리!$AB6 -> 0 | Q35: =버프정리!$AB6 -> 0 | R35: =버프정리!$AH6 -> 0 | S35: =버프정리!$AH6 -> 0 | T35: =버프정리!$AH6 -> 0 | U35: =버프정리!$AH6 -> 0
A36: 공방 | B36: 공격력증가 | C36: =버프정리!$D7 -> 1.5044639 | D36: =버프정리!$J7 -> 1.5044639 | E36: =버프정리!$J7 -> 1.5044639 | F36: =버프정리!$J7 -> 1.5044639 | G36: =버프정리!$J7 -> 1.5044639 | H36: =버프정리!$J7 -> 1.5044639 | I36: =버프정리!$P7 -> 1.5044639 | J36: =버프정리!$P7 -> 1.5044639 | K36: =버프정리!$P7 -> 1.5044639 | L36: =버프정리!$P7 -> 1.5044639 | M36: =버프정리!$V7 -> 0.2 | N36: =버프정리!$AB7 -> 1.5044639 | O36: =버프정리!$AB7 -> 1.5044639 | P36: =버프정리!$AB7 -> 1.5044639 | Q36: =버프정리!$AB7 -> 1.5044639 | R36: =버프정리!$AH7 -> 1.5044639 | S36: =버프정리!$AH7 -> 1.5044639 | T36: =버프정리!$AH7 -> 1.5044639 | U36: =버프정리!$AH7 -> 1.5044639
B37: 방어력감소 | C37: =버프정리!$D8 -> 0 | D37: =버프정리!$J8 -> 0 | E37: =버프정리!$J8 -> 0 | F37: =버프정리!$J8 -> 0 | G37: =버프정리!$J8 -> 0 | H37: =버프정리!$J8 -> 0 | I37: =버프정리!$P8 -> 0 | J37: =버프정리!$P8 -> 0 | K37: =버프정리!$P8 -> 0 | L37: =버프정리!$P8 -> 0 | M37: =버프정리!$V8 -> 0 | N37: =버프정리!$AB8 -> 0 | O37: =버프정리!$AB8 -> 0 | P37: =버프정리!$AB8 -> 0 | Q37: =버프정리!$AB8 -> 0 | R37: =버프정리!$AH8 -> 0 | S37: =버프정리!$AH8 -> 0 | T37: =버프정리!$AH8 -> 0 | U37: =버프정리!$AH8 -> 0
A38: 대미지유형별버프 (파츠딜은 다루기 어려우니 패스) | B38: 공격 | C38: =버프정리!$D9 -> 0.1504 | D38: =버프정리!$J9 -> 0.4904 | E38: =버프정리!$J9 -> 0.4904 | F38: =버프정리!$J9 -> 0.4904 | G38: =버프정리!$J9 -> 0.4904 | H38: =버프정리!$J9 -> 0.4904 | I38: =버프정리!$P9 -> 0.4904 | J38: =버프정리!$P9 -> 0.4904 | K38: =버프정리!$P9 -> 0.4904 | L38: =버프정리!$P9 -> 0.4904 | M38: =버프정리!$V9 -> 0 | N38: =버프정리!$AB9 -> 0.34 | O38: =버프정리!$AB9 -> 0.34 | P38: =버프정리!$AB9 -> 0.34 | Q38: =버프정리!$AB9 -> 0.34 | R38: =버프정리!$AH9 -> 0.34 | S38: =버프정리!$AH9 -> 0.34 | T38: =버프정리!$AH9 -> 0.34 | U38: =버프정리!$AH9 -> 0.34
B39: 방어력무시 | C39: =버프정리!$D10 -> 0 | D39: =버프정리!$J10 -> 0 | E39: =버프정리!$J10 -> 0 | F39: =버프정리!$J10 -> 0 | G39: =버프정리!$J10 -> 0 | H39: =버프정리!$J10 -> 0 | I39: =버프정리!$P10 -> 0 | J39: =버프정리!$P10 -> 0 | K39: =버프정리!$P10 -> 0 | L39: =버프정리!$P10 -> 0 | M39: =버프정리!$V10 -> 0 | N39: =버프정리!$AB10 -> 0 | O39: =버프정리!$AB10 -> 0 | P39: =버프정리!$AB10 -> 0 | Q39: =버프정리!$AB10 -> 0 | R39: =버프정리!$AH10 -> 0 | S39: =버프정리!$AH10 -> 0 | T39: =버프정리!$AH10 -> 0 | U39: =버프정리!$AH10 -> 0
B40: 관통 | C40: =버프정리!$D11 -> 0 | D40: =버프정리!$J11 -> 0 | E40: =버프정리!$J11 -> 0 | F40: =버프정리!$J11 -> 0 | G40: =버프정리!$J11 -> 0 | H40: =버프정리!$J11 -> 0 | I40: =버프정리!$P11 -> 0 | J40: =버프정리!$P11 -> 0 | K40: =버프정리!$P11 -> 0 | L40: =버프정리!$P11 -> 0 | M40: =버프정리!$V11 -> 0 | N40: =버프정리!$AB11 -> 0 | O40: =버프정리!$AB11 -> 0 | P40: =버프정리!$AB11 -> 0 | Q40: =버프정리!$AB11 -> 0 | R40: =버프정리!$AH11 -> 0 | S40: =버프정리!$AH11 -> 0 | T40: =버프정리!$AH11 -> 0 | U40: =버프정리!$AH11 -> 0
B41: 지속 | C41: =버프정리!$D12 -> 0 | D41: =버프정리!$J12 -> 0 | E41: =버프정리!$J12 -> 0 | F41: =버프정리!$J12 -> 0 | G41: =버프정리!$J12 -> 0 | H41: =버프정리!$J12 -> 0 | I41: =버프정리!$P12 -> 0 | J41: =버프정리!$P12 -> 0 | K41: =버프정리!$P12 -> 0 | L41: =버프정리!$P12 -> 0 | M41: =버프정리!$V12 -> 0 | N41: =버프정리!$AB12 -> 0 | O41: =버프정리!$AB12 -> 0 | P41: =버프정리!$AB12 -> 0 | Q41: =버프정리!$AB12 -> 0 | R41: =버프정리!$AH12 -> 0 | S41: =버프정리!$AH12 -> 0 | T41: =버프정리!$AH12 -> 0 | U41: =버프정리!$AH12 -> 0
B42: 발사체폭발 | C42: =버프정리!$D13 -> 0 | D42: =버프정리!$J13 -> 0.9203 | E42: =버프정리!$J13 -> 0.9203 | F42: =버프정리!$J13 -> 0.9203 | G42: =버프정리!$J13 -> 0.9203 | H42: =버프정리!$J13 -> 0.9203 | I42: =버프정리!$P13 -> 0.9203 | J42: =버프정리!$P13 -> 0.9203 | K42: =버프정리!$P13 -> 0.9203 | L42: =버프정리!$P13 -> 0.9203 | M42: =버프정리!$V13 -> 0 | N42: =버프정리!$AB13 -> 0.9203 | O42: =버프정리!$AB13 -> 0.9203 | P42: =버프정리!$AB13 -> 0.9203 | Q42: =버프정리!$AB13 -> 0.9203 | R42: =버프정리!$AH13 -> 0.9203 | S42: =버프정리!$AH13 -> 0.9203 | T42: =버프정리!$AH13 -> 0.9203 | U42: =버프정리!$AH13 -> 0.9203
B43: 발사체부착 | C43: =버프정리!$D14 -> 0 | D43: =버프정리!$J14 -> 0 | E43: =버프정리!$J14 -> 0 | F43: =버프정리!$J14 -> 0 | G43: =버프정리!$J14 -> 0 | H43: =버프정리!$J14 -> 0 | I43: =버프정리!$P14 -> 0 | J43: =버프정리!$P14 -> 0 | K43: =버프정리!$P14 -> 0 | L43: =버프정리!$P14 -> 0 | M43: =버프정리!$V14 -> 0 | N43: =버프정리!$AB14 -> 0 | O43: =버프정리!$AB14 -> 0 | P43: =버프정리!$AB14 -> 0 | Q43: =버프정리!$AB14 -> 0 | R43: =버프정리!$AH14 -> 0 | S43: =버프정리!$AH14 -> 0 | T43: =버프정리!$AH14 -> 0 | U43: =버프정리!$AH14 -> 0
...

Sheet 버프정리
E1: 0 | F1: 0 | G1: 0 | H1: 0 | I1: 0 | K1: 1 | L1: 1 | M1: 1 | N1: 1 | O1: 1 | Q1: 2 | R1: 2 | S1: 2 | T1: 2 | U1: 2 | W1: 3 | X1: 3 | Y1: 3 | Z1: 3 | AA1: 3 | AC1: 4 | AD1: 4 | AE1: 4 | AF1: 4 | AG1: 4 | AI1: 5 | AJ1: 5 | AK1: 5 | AL1: 5 | AM1: 5
C2: 소&장&큡 | D2: 자버직전 | E2: 딜러 | F2: 서포터1 | G2: 서포터2 | H2: 서포터3 | I2: 서포터4 | J2: 자버전반 | K2: 딜러 | L2: 서포터1 | M2: 서포터2 | N2: 서포터3 | O2: 서포터4 | P2: 자버후반 | Q2: 딜러 | R2: 서포터1 | S2: 서포터2 | T2: 서포터3 | U2: 서포터4 | V2: 자버이후 | W2: 딜러 | X2: 서포터1 | Y2: 서포터2 | Z2: 서포터3 | AA2: 서포터4 | AB2: 타버전반 | AC2: 딜러 | AD2: 서포터1 | AE2: 서포터2 | AF2: 서포터3 | AG2: 서포터4 | AH2: 타버후반 | AI2: 딜러 | AJ2: 서포터1 | AK2: 서포터2 | AL2: 서포터3 | AM2: 서포터4
D3: 합산 | E3: =메인!$F$4 -> 신데렐라 | F3: =메인!$G$4 -> 아니스 | G3: =메인!$H$4 -> 마스트 | H3: =메인!$I$4 -> 앵커 | I3: =메인!$J$4 -> 0 | J3: 합산 | K3: =메인!$F$4 -> 신데렐라 | L3: =메인!$G$4 -> 아니스 | M3: =메인!$H$4 -> 마스트 | N3: =메인!$I$4 -> 앵커 | O3: =메인!$J$4 -> 0 | P3: 합산 | Q3: =메인!$F$4 -> 신데렐라 | R3: =메인!$G$4 -> 아니스 | S3: =메인!$H$4 -> 마스트 | T3: =메인!$I$4 -> 앵커 | U3: =메인!$J$4 -> 0 | V3: 합산 | W3: =메인!$F$4 -> 신데렐라 | X3: =메인!$G$4 -> 아니스 | Y3: =메인!$H$4 -> 마스트 | Z3: =메인!$I$4 -> 앵커 | AA3: =메인!$J$4 -> 0 | AB3: 합산 | AC3: =메인!$F$4 -> 신데렐라 | AD3: =메인!$G$4 -> 아니스 | AE3: =메인!$H$4 -> 마스트 | AF3: =메인!$I$4 -> 앵커 | AG3: =메인!$J$4 -> 0 | AH3: 합산 | AI3: =메인!$F$4 -> 신데렐라 | AJ3: =메인!$G$4 -> 아니스 | AK3: =메인!$H$4 -> 마스트 | AL3: =메인!$I$4 -> 앵커 | AM3: =메인!$J$4 -> 0
A4: 시전자기준 | B4: 서포터기준공격력 | D4: =$C4+SUM(E4:I4) -> 143038.73 | E4: {=IFERROR(INDEX(딜러데이터!$C$3:$BBD$52, ROW()-ROW($B$4)+1, MATCH(E$3, 딜러데이터!$C$1:$AAM$1, 0)+E$1), 0)*메인!$F7} -> 0 | F4: {=IFERROR(INDEX(서포터데이터!$C$3:$AAW$53, ROW()-ROW($B$4)+1, MATCH(F$3, 서포터데이터!$C$1:$AAW$1, 0)+F$1), 0)*메인!$G7} -> 0 | G4: {=IFERROR(INDEX(서포터데이터!$C$3:$AAW$53, ROW()-ROW($B$4)+1, MATCH(G$3, 서포터데이터!$C$1:$AAW$1, 0)+G$1), 0)*메인!$H7} -> 104571.39 | H4: {=IFERROR(INDEX(서포터데이터!$C$3:$AAW$53, ROW()-ROW($B$4)+1, MATCH(H$3, 서포터데이터!$C$1:$AAW$1, 0)+H$1), 0)*메인!$I7} -> 38467.334 | I4: {=IFERROR(INDEX(서포터데이터!$C$3:$AAW$53, ROW()-ROW($B$4)+1, MATCH(I$3, 서포터데이터!$C$1:$AAW$1, 0)+I$1), 0)*메인!$J7} -> 0 | J4: =$C4+SUM(K4:O4) -> 174856.42 | K4: {=IFERROR(INDEX(딜러데이터!$C$3:$BBD$52, ROW()-ROW($B$4)+1, MATCH(K$3, 딜러데이터!$C$1:$AAM$1, 0)+K$1), 0)*메인!$F7} -> 0 | L4: {=IFERROR(INDEX(서포터데이터!$C$3:$AAW$53, ROW()-ROW($B$4)+1, MATCH(L$3, 서포터데이터!$C$1:$AAW$1, 0)+L$1), 0)*메인!$G7} -> 31817.69 | M4: {=IFERROR(INDEX(서포터데이터!$C$3:$AAW$53, ROW()-ROW($B$4)+1, MATCH(M$3, 서포터데이터!$C$1:$AAW$1, 0)+M$1), 0)*메인!$H7} -> 104571.39 | N4: {=IFERROR(INDEX(서포터데이터!$C$3:$AAW$53, ROW()-ROW($B$4)+1, MATCH(N$3, 서포터데이터!$C$1:$AAW$1, 0)+N$1), 0)*메인!$I7} -> 38467.334 | O4: {=IFERROR(INDEX(서포터데이터!$C$3:$AAW$53, ROW()-ROW($B$4)+1, MATCH(O$3, 서포터데이터!$C$1:$AAW$1, 0)+O$1), 0)*메인!$J7} -> 0 | P4: =$C4+SUM(Q4:U4) -> 136389.08 | Q4: {=IFERROR(INDEX(딜러데이터!$C$3:$BBD$52, ROW()-ROW($B$4)+1, MATCH(Q$3, 딜러데이터!$C$1:$AAM$1, 0)+Q$1), 0)*메인!$F7} -> 0 | R4: {=IFERROR(INDEX(서포터데이터!$C$3:$AAW$53, ROW()-ROW($B$4)+1, MATCH(R$3, 서포터데이터!$C$1:$AAW$1, 0)+R$1), 0)*메인!$G7} -> 31817.69 | S4: {=IFERROR(INDEX(서포터데이터!$C$3:$AAW$53, ROW()-ROW($B$4)+1, MATCH(S$3, 서포터데이터!$C$1:$AAW$1, 0)+S$1), 0)*메인!$H7} -> 104571.39 | T4: {=IFERROR(INDEX(서포터데이터!$C$3:$AAW$53, ROW()-ROW($B$4)+1, MATCH(T$3, 서포터데이터!$C$1:$AAW$1, 0)+T$1), 0)*메인!$I7} -> 0 | U4: {=IFERROR(INDEX(서포터데이터!$C$3:$AAW$53, ROW()-ROW($B$4)+1, MATCH(U$3, 서포터데이터!$C$1:$AAW$1, 0)+U$1), 0)*메인!$J7} -> 0 | V4: =$C4+SUM(W4:AA4) -> 76934.668 | W4: {=IFERROR(INDEX(딜러데이터!$C$3:$BBD$52, ROW()-ROW($B$4)+1, MATCH(W$3, 딜러데이터!$C$1:$AAM$1, 0)+W$1), 0)*메인!$F7} -> 0 | X4: {=IFERROR(INDEX(서포터데이터!$C$3:$AAW$53, ROW()-ROW($B$4)+1, MATCH(X$3, 서포터데이터!$C$1:$AAW$1, 0)+X$1), 0)*메인!$G7} -> 0 | Y4: {=IFERROR(INDEX(서포터데이터!$C$3:$AAW$53, ROW()-ROW($B$4)+1, MATCH(Y$3, 서포터데이터!$C$1:$AAW$1, 0)+Y$1), 0)*메인!$H7} -> 38467.334 | Z4: {=IFERROR(INDEX(서포터데이터!$C$3:$AAW$53, ROW()-ROW($B$4)+1, MATCH(Z$3, 서포터데이터!$C$1:$AAW$1, 0)+Z$1), 0)*메인!$I7} -> 38467.334 | AA4: {=IFERROR(INDEX(서포터데이터!$C$3:$AAW$53, ROW()-ROW($B$4)+1, MATCH(AA$3, 서포터데이터!$C$1:$AAW$1, 0)+AA$1), 0)*메인!$J7} -> 0 | AB4: =$C4+SUM(AC4:AG4) -> 141804.39 | AC4: {=IFERROR(INDEX(딜러데이터!$C$3:$BBD$52, ROW()-ROW($B$4)+1, MATCH(AC$3, 딜러데이터!$C$1:$AAM$1, 0)+AC$1), 0)*메인!$F7} -> 0 | AD4: {=IFERROR(INDEX(서포터데이터!$C$3:$AAW$53, ROW()-ROW($B$4)+1, MATCH(AD$3, 서포터데이터!$C$1:$AAW$1, 0)+AD$1), 0)*메인!$G7} -> 31817.69 | AE4: {=IFERROR(INDEX(서포터데이터!$C$3:$AAW$53, ROW()-ROW($B$4)+1, MATCH(AE$3, 서포터데이터!$C$1:$AAW$1, 0)+AE$1), 0)*메인!$H7} -> 38467.334 | AF4: {=IFERROR(INDEX(서포터데이터!$C$3:$AAW$53, ROW()-ROW($B$4)+1, MATCH(AF$3, 서포터데이터!$C$1:$AAW$1, 0)+AF$1), 0)*메인!$I7} -> 71519.363 | AG4: {=IFERROR(INDEX(서포터데이터!$C$3:$AAW$53, ROW()-ROW($B$4)+1, MATCH(AG$3, 서포터데이터!$C$1:$AAW$1, 0)+AG$1), 0)*메인!$J7} -> 0 | AH4: =$C4+SUM(AI4:AM4) -> 103337.05 | AI4: {=IFERROR(INDEX(딜러데이터!$C$3:$BBD$52, ROW()-ROW($B$4)+1, MATCH(AI$3, 딜러데이터!$C$1:$AAM$1, 0)+AI$1), 0)*메인!$F7} -> 0 | AJ4: {=IFERROR(INDEX(서포터데이터!$C$3:$AAW$53, ROW()-ROW($B$4)+1, MATCH(AJ$3, 서포터데이터!$C$1:$AAW$1, 0)+AJ$1), 0)*메인!$G7} -> 31817.69 | AK4: {=IFERROR(INDEX(서포터데이터!$C$3:$AAW$53, ROW()-ROW($B$4)+1, MATCH(AK$3, 서포터데이터!$C$1:$AAW$1, 0)+AK$1), 0)*메인!$H7} -> 38467.334 | AL4: {=IFERROR(INDEX(서포터데이터!$C$3:$AAW$53, ROW()-ROW($B$4)+1, MATCH(AL$3, 서포터데이터!$C$1:$AAW$1, 0)+AL$1), 0)*메인!$I7} -> 33052.03 | AM4: {=IFERROR(INDEX(서포터데이터!$C$3:$AAW$53, ROW()-ROW($B$4)+1, MATCH(AM$3, 서포터데이터!$C$1:$AAW$1, 0)+AM$1), 0)*메인!$J7} -> 0
B5: 서포터기준체력(만) | D5: =$C5+SUM(E5:I5) -> 0 | E5: {=IFERROR(INDEX(딜러데이터!$C$3:$BBD$52, ROW()-ROW($B$4)+1, MATCH(E$3, 딜러데이터!$C$1:$AAM$1, 0)+E$1), 0)*메인!$F8} -> 0 | F5: {=IFERROR(INDEX(서포터데이터!$C$3:$AAW$53, ROW()-ROW($B$4)+1, MATCH(F$3, 서포터데이터!$C$1:$AAW$1, 0)+F$1), 0)*메인!$G8} -> 0 | G5: {=IFERROR(INDEX(서포터데이터!$C$3:$AAW$53, ROW()-ROW($B$4)+1, MATCH(G$3, 서포터데이터!$C$1:$AAW$1, 0)+G$1), 0)*메인!$H8} -> 0 | H5: {=IFERROR(INDEX(서포터데이터!$C$3:$AAW$53, ROW()-ROW($B$4)+1, MATCH(H$3, 서포터데이터!$C$1:$AAW$1, 0)+H$1), 0)*메인!$I8} -> 0 | I5: {=IFERROR(INDEX(서포터데이터!$C$3:$AAW$53, ROW()-ROW($B$4)+1, MATCH(I$3, 서포터데이터!$C$1:$AAW$1, 0)+I$1), 0)*메인!$J8} -> 0 | J5: =$C5+SUM(K5:O5) -> 0 | K5: {=IFERROR(INDEX(딜러데이터!$C$3:$BBD$52, ROW()-ROW($B$4)+1, MATCH(K$3, 딜러데이터!$C$1:$AAM$1, 0)+K$1), 0)*메인!$F8} -> 0 | L5: {=IFERROR(INDEX(서포터데이터!$C$3:$AAW$53, ROW()-ROW($B$4)+1, MATCH(L$3, 서포터데이터!$C$1:$AAW$1, 0)+L$1), 0)*메인!$G8} -> 0 | M5: {=IFERROR(INDEX(서포터데이터!$C$3:$AAW$53, ROW()-ROW($B$4)+1, MATCH(M$3, 서포터데이터!$C$1:$AAW$1, 0)+M$1), 0)*메인!$H8} -> 0 | N5: {=IFERROR(INDEX(서포터데이터!$C$3:$AAW$53, ROW()-ROW($B$4)+1, MATCH(N$3, 서포터데이터!$C$1:$AAW$1, 0)+N$1), 0)*메인!$I8} -> 0 | O5: {=IFERROR(INDEX(서포터데이터!$C$3:$AAW$53, ROW()-ROW($B$4)+1, MATCH(O$3, 서포터데이터!$C$1:$AAW$1, 0)+O$1), 0)*메인!$J8} -> 0 | P5: =$C5+SUM(Q5:U5) -> 0 | Q5: {=IFERROR(INDEX(딜러데이터!$C$3:$BBD$52, ROW()-ROW($B$4)+1, MATCH(Q$3, 딜러데이터!$C$1:$AAM$1, 0)+Q$1), 0)*메인!$F8} -> 0 | R5: {=IFERROR(INDEX(서포터데이터!$C$3:$AAW$53, ROW()-ROW($B$4)+1, MATCH(R$3, 서포터데이터!$C$1:$AAW$1, 0)+R$1), 0)*메인!$G8} -> 0 | S5: {=IFERROR(INDEX(서포터데이터!$C$3:$AAW$53, ROW()-ROW($B$4)+1, MATCH(S$3, 서포터데이터!$C$1:$AAW$1, 0)+S$1), 0)*메인!$H8} -> 0 | T5: {=IFERROR(INDEX(서포터데이터!$C$3:$AAW$53, ROW()-ROW($B$4)+1, MATCH(T$3, 서포터데이터!$C$1:$AAW$1, 0)+T$1), 0)*메인!$I8} -> 0 | U5: {=IFERROR(INDEX(서포터데이터!$C$3:$AAW$53, ROW()-ROW($B$4)+1, MATCH(U$3, 서포터데이터!$C$1:$AAW$1, 0)+U$1), 0)*메인!$J8} -> 0 | V5: =$C5+SUM(W5:AA5) -> 0 | W5: {=IFERROR(INDEX(딜러데이터!$C$3:$BBD$52, ROW()-ROW($B$4)+1, MATCH(W$3, 딜러데이터!$C$1:$AAM$1, 0)+W$1), 0)*메인!$F8} -> 0 | X5: {=IFERROR(INDEX(서포터데이터!$C$3:$AAW$53, ROW()-ROW($B$4)+1, MATCH(X$3, 서포터데이터!$C$1:$AAW$1, 0)+X$1), 0)*메인!$G8} -> 0 | Y5: {=IFERROR(INDEX(서포터데이터!$C$3:$AAW$53, ROW()-ROW($B$4)+1, MATCH(Y$3, 서포터데이터!$C$1:$AAW$1, 0)+Y$1), 0)*메인!$H8} -> 0 | Z5: {=IFERROR(INDEX(서포터데이터!$C$3:$AAW$53, ROW()-ROW($B$4)+1, MATCH(Z$3, 서포터데이터!$C$1:$AAW$1, 0)+Z$1), 0)*메인!$I8} -> 0 | AA5: {=IFERROR(INDEX(서포터데이터!$C$3:$AAW$53, ROW()-ROW($B$4)+1, MATCH(AA$3, 서포터데이터!$C$1:$AAW$1, 0)+AA$1), 0)*메인!$J8} -> 0 | AB5: =$C5+SUM(AC5:AG5) -> 0 | AC5: {=IFERROR(INDEX(딜러데이터!$C$3:$BBD$52, ROW()-ROW($B$4)+1, MATCH(AC$3, 딜러데이터!$C$1:$AAM$1, 0)+AC$1), 0)*메인!$F8} -> 0 | AD5: {=IFERROR(INDEX(서포터데이터!$C$3:$AAW$53, ROW()-ROW($B$4)+1, MATCH(AD$3, 서포터데이터!$C$1:$AAW$1, 0)+AD$1), 0)*메인!$G8} -> 0 | AE5: {=IFERROR(INDEX(서포터데이터!$C$3:$AAW$53, ROW()-ROW($B$4)+1, MATCH(AE$3, 서포터데이터!$C$1:$AAW$1, 0)+AE$1), 0)*메인!$H8} -> 0 | AF5: {=IFERROR(INDEX(서포터데이터!$C$3:$AAW$53, ROW()-ROW($B$4)+1, MATCH(AF$3, 서포터데이터!$C$1:$AAW$1, 0)+AF$1), 0)*메인!$I8} -> 0 | AG5: {=IFERROR(INDEX(서포터데이터!$C$3:$AAW$53, ROW()-ROW($B$4)+1, MATCH(AG$3, 서포터데이터!$C$1:$AAW$1, 0)+AG$1), 0)*메인!$J8} -> 0 | AH5: =$C5+SUM(AI5:AM5) -> 0 | AI5: {=IFERROR(INDEX(딜러데이터!$C$3:$BBD$52, ROW()-ROW($B$4)+1, MATCH(AI$3, 딜러데이터!$C$1:$AAM$1, 0)+AI$1), 0)*메인!$F8} -> 0 | AJ5: {=IFERROR(INDEX(서포터데이터!$C$3:$AAW$53, ROW()-ROW($B$4)+1, MATCH(AJ$3, 서포터데이터!$C$1:$AAW$1, 0)+AJ$1), 0)*메인!$G8} -> 0 | AK5: {=IFERROR(INDEX(서포터데이터!$C$3:$AAW$53, ROW()-ROW($B$4)+1, MATCH(AK$3, 서포터데이터!$C$1:$AAW$1, 0)+AK$1), 0)*메인!$H8} -> 0 | AL5: {=IFERROR(INDEX(서포터데이터!$C$3:$AAW$53, ROW()-ROW($B$4)+1, MATCH(AL$3, 서포터데이터!$C$1:$AAW$1, 0)+AL$1), 0)*메인!$I8} -> 0 | AM5: {=IFERROR(INDEX(서포터데이터!$C$3:$AAW$53, ROW()-ROW($B$4)+1, MATCH(AM$3, 서포터데이터!$C$1:$AAW$1, 0)+AM$1), 0)*메인!$J8} -> 0
